Workbook
Name Tile_Level_Carpet: 'Tile Product Lists'!$K$2:$K$30
Name Tile_Level_Curb: 'Tile Product Lists'!$J$2:$J$30
Name Tile_Level_Floor_Tile: 'Tile Product Lists'!$D$2:$D$30
Name Tile_Level_Kitchen_Backsplash: 'Tile Product Lists'!$C$2:$C$30
Name Tile_Level_Knee_Wall_Cap: 'Tile Product Lists'!$I$2:$I$30
Name Tile_Level_List: 'Tile Product Lists'!$B$2:$B$30
Name Tile_Level_Listel: 'Tile Product Lists'!$E$2:$E$30
Name Tile_Level_LVP: 'Tile Product Lists'!$L$2:$L$30
Name Tile_Level_Shower_Pan_Tile: 'Tile Product Lists'!$F$2:$F$30
Name Tile_Level_Shower_Tub_Wall_Tile: 'Tile Product Lists'!$G$2:$G$30
Name Tile_Level_Sill: 'Tile Product Lists'!$H$2:$H$30
Name Tile_Level_Wood: 'Tile Product Lists'!$M$2:$M$30
Name Tile_Product_Carpet_Level_1: 'Tile Product Lists'!$BD$2:$BD$30
Name Tile_Product_Curb_Level_1: 'Tile Product Lists'!$BC$2:$BC$30
Name Tile_Product_Floor_Tile_Level_1: 'Tile Product Lists'!$Y$2:$Y$30
Name Tile_Product_Floor_Tile_Level_2: 'Tile Product Lists'!$Z$2:$Z$30
Name Tile_Product_Floor_Tile_Level_3: 'Tile Product Lists'!$AA$2:$AA$30
Name Tile_Product_Floor_Tile_Level_4: 'Tile Product Lists'!$AB$2:$AB$30
Name Tile_Product_Floor_Tile_Level_5: 'Tile Product Lists'!$AC$2:$AC$30
Name Tile_Product_Floor_Tile_Level_6: 'Tile Product Lists'!$AD$2:$AD$30
Name Tile_Product_Floor_Tile_Level_7: 'Tile Product Lists'!$AE$2:$AE$30
Name Tile_Product_Floor_Tile_Level_8: 'Tile Product Lists'!$AF$2:$AF$30
Name Tile_Product_Floor_Tile_Level_9: 'Tile Product Lists'!$AG$2:$AG$30
Name Tile_Product_Kitchen_Backsplash_Level_1: 'Tile Product Lists'!$P$2:$P$30
Name Tile_Product_Kitchen_Backsplash_Level_2: 'Tile Product Lists'!$Q$2:$Q$30
Name Tile_Product_Kitchen_Backsplash_Level_3: 'Tile Product Lists'!$R$2:$R$30
Name Tile_Product_Kitchen_Backsplash_Level_4: 'Tile Product Lists'!$S$2:$S$30
Name Tile_Product_Kitchen_Backsplash_Level_5: 'Tile Product Lists'!$T$2:$T$30
Name Tile_Product_Kitchen_Backsplash_Level_6: 'Tile Product Lists'!$U$2:$U$30
Name Tile_Product_Kitchen_Backsplash_Level_7: 'Tile Product Lists'!$V$2:$V$30
Name Tile_Product_Kitchen_Backsplash_Level_8: 'Tile Product Lists'!$W$2:$W$30
Name Tile_Product_Kitchen_Backsplash_Level_9: 'Tile Product Lists'!$X$2:$X$30
Name Tile_Product_Knee_Wall_Cap_Level_1: 'Tile Product Lists'!$BB$2:$BB$30
Name Tile_Product_Listel_Level_1: 'Tile Product Lists'!$AH$2:$AH$30
Name Tile_Product_Listel_Level_2: 'Tile Product Lists'!$AI$2:$AI$30
Name Tile_Product_Listel_Level_3: 'Tile Product Lists'!$AJ$2:$AJ29
Name Tile_Product_Listel_Level_4: 'Tile Product Lists'!$AK$2:$AK$30
Name Tile_Product_Listel_Level_5: 'Tile Product Lists'!$AL$2:$AL$30
Name Tile_Product_LVP_Level_1: 'Tile Product Lists'!$BE$2:$BE$30
Name Tile_Product_Shower_Pan_Tile_Level_1: 'Tile Product Lists'!$AM$2:$AM$30
Name Tile_Product_Shower_Pan_Tile_Level_2: 'Tile Product Lists'!$AN$2:$AN$30
Name Tile_Product_Shower_Pan_Tile_Level_3: 'Tile Product Lists'!$AO$2:$AO$30
Name Tile_Product_Shower_Pan_Tile_Level_4: 'Tile Product Lists'!$AP$2:$AP$30
Name Tile_Product_Shower_Pan_Tile_Level_5: 'Tile Product Lists'!$AQ$2:$AQ$30
Name Tile_Product_Shower_Tub_Wall_Tile_Level_1: 'Tile Product Lists'!$AR$2:$AR$30
Name Tile_Product_Shower_Tub_Wall_Tile_Level_2: 'Tile Product Lists'!$AS$2:$AS$30
Name Tile_Product_Shower_Tub_Wall_Tile_Level_3: 'Tile Product Lists'!$AT$2:$AT$30
Name Tile_Product_Shower_Tub_Wall_Tile_Level_4: 'Tile Product Lists'!$AU$2:$AU$30
Name Tile_Product_Shower_Tub_Wall_Tile_Level_5: 'Tile Product Lists'!$AV$2:$AV$30
Name Tile_Product_Shower_Tub_Wall_Tile_Level_6: 'Tile Product Lists'!$AW$2:$AW$30
Name Tile_Product_Shower_Tub_Wall_Tile_Level_7: 'Tile Product Lists'!$AX$2:$AX$30
Name Tile_Product_Shower_Tub_Wall_Tile_Level_8: 'Tile Product Lists'!$AY$2:$AY$30
Name Tile_Product_Shower_Tub_Wall_Tile_Level_9: 'Tile Product Lists'!$AZ$2:$AZ$30
Name Tile_Product_Sill_Level_1: 'Tile Product Lists'!$BA$2:$BA$30
Name Tile_Product_Wood_Level_1: 'Tile Product Lists'!$BF$2:$BF$30
Name Tile_Section_List: 'Tile Product Lists'!$A$2:$A$30

Sheet Customer Option Cover Page
D2: Once selections have been reviewed and signed by both parties, they are considered final. We understand that adjustments may occasionally be requested; however, changes made after approval and/or after construction has begun may result in additional costs and are subject to the Builder’s review and approval. To ensure clarity and accuracy, any changes must be documented and signed by both parties prior to implementation. This Customer Option Form agreement is non-refundable. However, if any selected option is not installed, a full refund for the individual option(s) will be credited at closing
C3: CUSTOMER OPTION FORM #1
B5: DATE: | C5: =TODAY() -> 46259
B6: CUSTOMER: | C6: John Doe | E6: Allowance Estimated Pricing Subject to change, based on final installed price
B7: JOB ADDRESS: | C7: 123 avenue
B8: ALLOWANCES
B9: PRICE REQUEST ITEMS BY HOMEOWNER | D9: Please Note: Pricing may fluctuate on items that are priced out for the Homeowners from the time of price request to time of homeowner approval. A charge or credit will apply at the time of ordering.
B10: "Ballpark" Prelim. Estimate
B11: CLARIFICATIONS (NO PRICE CHANGE)
B12: PRICING READY TO SHOW HOMEOWNER
B13: HOMEOWNER REVIEWING
B14: PRICING APPROVED BY HOMEOWNER
B15: Eric Olsen
B16: Sarah Brown
B17: Stephanie Throop
B18: Ashley Birmingham
B19: Monique Lumsley
B20: TOP PRIORITY
B21: (Select Status)
B22: Category | C22: Description | D22: Date | E22: Revised by: | F22: Allowance | G22: Final price | H22: Difference | I22: Status
B23: Allowance | C23: Designer Time
B24: Allowance | C24: Appliance Allowance | H24: Overage To be paid directly to the Appliance Co. | I24: ALLOWANCES
B25: Allowance | C25: Cabinetry Allowance: This is allowance for base cabinetry throughout the home. Added items or options will be priced separately below. | I25: ALLOWANCES
B26: Allowance | C26: Cabinetry Hardware Standard: | H26: Placeholder | I26: ALLOWANCES
B27: Allowance | C27: Drywall/Duro/Densglass Material Allowance: | I27: ALLOWANCES
B28: Allowance | C28: Electrical Allowance: This allowance is for base electrical for the home. Upgraded or added items will be priced separately below. | I28: ALLOWANCES
B29: Allowance | C29: Exterior Doors Allowance: | I29: ALLOWANCES
B30: Allowance | C30: Exterior Railing Allowance: | I30: ALLOWANCES
B31: Allowance | C31: Garage Door Allowance: | I31: ALLOWANCES
B32: Allowance | C32: Granite Countertop Allowance: | I32: ALLOWANCES
B33: Allowance | C33: Impact Fees Allowance: | I33: ALLOWANCES
B34: Allowance | C34: Interior Railing Allowance: | I34: ALLOWANCES
B35: Allowance | C35: Landscaping Allowance: | H35: Overage To be paid directly to the Landscaping Co. | I35: ALLOWANCES
B36: Allowance | C36: Light Fixture Allowance | H36: Overage To be paid directly to the Lighting Co. | I36: ALLOWANCES
B37: Allowance | C37: Lumber Allowance: | I37: ALLOWANCES
B38: Allowance | C38: Paver Allowance: More may be needed once survey is finalized and approved. | I38: ALLOWANCES
B39: Allowance | C39: Plumbing Allowance: This allowance is for base plumbing for the home. Upgraded or added items will be priced separately below. | I39: ALLOWANCES
B40: Allowance | C40: Pool Allowance: | H40: Overage To be paid directly to the Pool Co. | I40: ALLOWANCES
B41: Allowance | C41: Roofing Allowance: | I41: ALLOWANCES
B42: Allowance | C42: Sitework Allowance: THERE MAY BE ADDITONAL WORK ON TH LOT AT THE END OF THE PROJECT AS WELL AS POTENTIAL DEGRASS OF AREAS WE LEAVE UNITL THE END. | I42: ALLOWANCES
...

Sheet Allowances
A1: ='Customer Option Cover Page'!C6 -> John Doe
A2: ='Customer Option Cover Page'!C7 -> 123 avenue
B3: DATE: | C3: =TODAY() -> 46259
B4: CUSTOMER: | C4: ='Customer Option Cover Page'!C6 -> John Doe
B5: JOB ADDRESS: | C5: ='Customer Option Cover Page'!C7 -> 123 avenue
B7: Category | C7: Description | D7: Date | E7: Allowance | F7: Actuals | G7: Difference
B8: Allowance | C8: Drywall/Duro/Densglass Material Allowance:
B9: Allowance | C9: Electrical Allowance: This allowance is for base electrical for the home. Upgraded or added items will be priced separately below.
B10: Allowance | C10: Impact Fees Allowance:
B11: Allowance | C11: Lumber Allowance:
B12: Allowance | C12: Plumbing Allowance: This allowance is for base plumbing for the home. Upgraded or added items will be priced separately below.
B13: Allowance | C13: Roofing Allowance:
B14: Allowance | C14: Sitework Allowance: THERE MAY BE ADDITONAL WORK ON TH LOT AT THE END OF THE PROJECT AS WELL AS POTENTIAL DEGRASS OF AREAS WE LEAVE UNITL THE END.
B15: Allowance | C15: Truss Allowance
B16: Allowance | C16: Windows Allowance:

Sheet Options
A1: ='Customer Option Cover Page'!C6 -> John Doe
A2: ='Customer Option Cover Page'!C7 -> 123 avenue
B3: DATE: | C3: =TODAY() -> 46259
B4: CUSTOMER: | C4: =A1 -> John Doe
B5: JOB ADDRESS: | C5: =A2 -> 123 avenue
B7: Category | C7: Description | D7: Date | E7: Revised by: | F7: Contract Pricing Page | G7: Final price | H7: Difference

Sheet Countertops
B2: Countertop Quick Pricing Sheet | L2: ='Customer Option Cover Page'!C6 -> John Doe
B3: =U18 -> *All pricing displayed on this page is subject to change at the sole discression of Olsen Custom Homes. Pricing will be finalized via a customer option form.* | L3: ='Customer Option Cover Page'!C7 -> 123 avenue
B4: Designer Information | K4: Estimator | U4: Summary | X4: Instructions
B5: Area | C5: Type | D5: Detail | E5: Product Name | F5: Level | G5: Included? | H5: Edge Style | I5: Cutouts? | J5: Notes | K5: Qty_Est | L5: Qty_Pad | M5: Units | N5: $ / Unit | O5: Olsen Total | P5: Included | Q5: Difference | R5: Charge HO | U5: Allowance Total: | V5: 30000 | X5: **Please read this and follow the process EXACTLY**
L6: 0.1 | R6: 0.65 | X6: Instructions for ESTIMATOR
B7: Kitchen | U7: Area | V7: Charge to HO | X7: Instructions for ESTIMATOR (BEFORE-HO meeting)
B8: Countertop #1 | C8: Countertop Surface | D8: Surface Type | E8: Dallas White | F8: =VLOOKUP(E8,Counter_Pricing[[Material_Name]:[Level]],5,0) -> Level 1 | K8: 92 | L8: =K8*(1+$L$6) -> 101.2 | M8: SF | N8: =INDEX(Counter_Pricing[Olsen_Cost],MATCH(F8,Counter_Pricing[Level])) -> 38 | O8: =L8*N8 -> 3845.6 | P8: =(L8/SUM($L$8:$L$137))*$V$5 -> 255.3664 | Q8: =O8-P8 -> 3590.2336 | R8: =IF(Q8>0,Q8/$R$6,Q8) -> 5523.4363 | U8: =B7 -> Kitchen | V8: =R25 -> 45055.758 | X8: Step #1: Input correct allowance total in cell V5
B9: Countertop #1 | C9: Edge Type | D9: Eased Edge | E9: Eased Edge | F9: =VLOOKUP(E9,Counter_Pricing[[Material_Name]:[Level]],5,0) -> Labor | K9: 93 | L9: =K9*(1+$L$6) -> 102.3 | M9: LF | N9: =INDEX(Counter_Pricing[Olsen_Cost],MATCH(F9,Counter_Pricing[Level])) -> 0 | O9: =L9*N9 -> 0 | P9: =(L9/SUM($L$8:$L$137))*$V$5 -> 258.14212 | Q9: =O9-P9 -> -258.14212 | R9: =IF(Q9>0,Q9/$R$6,Q9) -> -258.14212 | U9: =B26 -> Master Bathroom | V9: =R41 -> 45055.758 | X9: Step #2: Assign all Rooms in BLACK Rows (7, 31,44, 57,70,83,96,109,122)
B10: Countertop #1 | C10: Cutout | D10: Sink (Undermount) | E10: Sink Cutout | F10: =VLOOKUP(E10,Counter_Pricing[[Material_Name]:[Level]],5,0) -> Labor | K10: 94 | L10: =K10*(1+$L$6) -> 103.4 | M10: SF | N10: =INDEX(Counter_Pricing[Olsen_Cost],MATCH(F10,Counter_Pricing[Level])) -> 0 | O10: =L10*N10 -> 0 | P10: =(L10/SUM($L$8:$L$137))*$V$5 -> 260.91784 | Q10: =O10-P10 -> -260.91784 | R10: =IF(Q10>0,Q10/$R$6,Q10) -> -260.91784 | U10: =B42 -> Bathroom #2 | V10: =R57 -> 45055.758 | X10: Step #3: Assign all areas receiving tile Column B
B11: Countertop #2 | C11: Countertop Surface | D11: Surface Type | E11: Dallas White | F11: =VLOOKUP(E11,Counter_Pricing[[Material_Name]:[Level]],5,0) -> Level 1 | K11: 95 | L11: =K11*(1+$L$6) -> 104.5 | M11: SF | N11: =INDEX(Counter_Pricing[Olsen_Cost],MATCH(F11,Counter_Pricing[Level])) -> 38 | O11: =L11*N11 -> 3971 | P11: =(L11/SUM($L$8:$L$137))*$V$5 -> 263.69356 | Q11: =O11-P11 -> 3707.3064 | R11: =IF(Q11>0,Q11/$R$6,Q11) -> 5703.5484 | U11: =B58 -> Bathroom #3 | V11: =R73 -> 45055.758 | X11: Step #4: Input each square footage estimate in Column L
B12: Countertop #2 | C12: Edge Type | D12: Mitered Edge | E12: Mitered Edge | F12: =VLOOKUP(E12,Counter_Pricing[[Material_Name]:[Level]],5,0) -> Labor | K12: 96 | L12: =K12*(1+$L$6) -> 105.6 | M12: SF | N12: =INDEX(Counter_Pricing[Olsen_Cost],MATCH(F12,Counter_Pricing[Level])) -> 0 | O12: =L12*N12 -> 0 | P12: =(L12/SUM($L$8:$L$137))*$V$5 -> 266.46928 | Q12: =O12-P12 -> -266.46928 | R12: =IF(Q12>0,Q12/$R$6,Q12) -> -266.46928 | U12: =B74 -> Bathroom #4 | V12: =R89 -> 45055.758 | X12: Step #5: Hide Columns L, Q, and R (highlighted in red)
B13: Countertop #2 | C13: Cutout | D13: Cooktop | E13: Sink Cutout | F13: =VLOOKUP(E13,Counter_Pricing[[Material_Name]:[Level]],5,0) -> Labor | K13: 97 | L13: =K13*(1+$L$6) -> 106.7 | M13: SF | N13: =INDEX(Counter_Pricing[Olsen_Cost],MATCH(F13,Counter_Pricing[Level])) -> 0 | O13: =L13*N13 -> 0 | P13: =(L13/SUM($L$8:$L$137))*$V$5 -> 269.245 | Q13: =O13-P13 -> -269.245 | R13: =IF(Q13>0,Q13/$R$6,Q13) -> -269.245 | U13: =B86 -> Countertop | V13: =R105 -> #N/A | X13: Step #6: Verify Pricing is correct at bottom of sheet
B14: Countertop #2 | C14: Cutout | D14: Sink (Undermount) | E14: Sink Cutout | F14: =VLOOKUP(E14,Counter_Pricing[[Material_Name]:[Level]],5,0) -> Labor | K14: 98 | L14: =K14*(1+$L$6) -> 107.8 | M14: SF | N14: =INDEX(Counter_Pricing[Olsen_Cost],MATCH(F14,Counter_Pricing[Level])) -> 0 | O14: =L14*N14 -> 0 | P14: =(L14/SUM($L$8:$L$137))*$V$5 -> 272.02073 | Q14: =O14-P14 -> -272.02073 | R14: =IF(Q14>0,Q14/$R$6,Q14) -> -272.02073 | U14: =B90 -> Pantry | V14: =R105 -> #N/A | X14: Instructions for DESIGNER (BEFORE HO Meeting)
B15: Island Countertop | C15: Countertop Surface | D15: Surface Type | E15: Dallas White | F15: =VLOOKUP(E15,Counter_Pricing[[Material_Name]:[Level]],5,0) -> Level 1 | K15: 95 | L15: =K15*(1+$L$6) -> 104.5 | M15: SF | N15: =INDEX(Counter_Pricing[Olsen_Cost],MATCH(F15,Counter_Pricing[Level])) -> 38 | O15: =L15*N15 -> 3971 | P15: =(L15/SUM($L$8:$L$137))*$V$5 -> 263.69356 | Q15: =O15-P15 -> 3707.3064 | R15: =IF(Q15>0,Q15/$R$6,Q15) -> 5703.5484 | U15: =B106 -> 0 | V15: =R121 -> #N/A | X15: Step #1: Input any selections from BT if client has already made them
B16: Island Countertop | C16: Edge Type | D16: Eased Edge | E16: Eased Edge | F16: =VLOOKUP(E16,Counter_Pricing[[Material_Name]:[Level]],5,0) -> Labor | K16: 96 | L16: =K16*(1+$L$6) -> 105.6 | M16: SF | N16: =INDEX(Counter_Pricing[Olsen_Cost],MATCH(F16,Counter_Pricing[Level])) -> 0 | O16: =L16*N16 -> 0 | P16: =(L16/SUM($L$8:$L$137))*$V$5 -> 266.46928 | Q16: =O16-P16 -> -266.46928 | R16: =IF(Q16>0,Q16/$R$6,Q16) -> -266.46928 | U16: =B122 -> 0 | V16: =R137 -> #N/A | X16: Step #2: Verify Estimator has input ALL area information in Column L
B17: Island Countertop | C17: Waterfall Surface | D17: Surface Type | E17: Dallas White | F17: =VLOOKUP(E17,Counter_Pricing[[Material_Name]:[Level]],5,0) -> Level 1 | H17: Left Waterfall | K17: 97 | L17: =K17*(1+$L$6) -> 106.7 | M17: SF | N17: =INDEX(Counter_Pricing[Olsen_Cost],MATCH(F17,Counter_Pricing[Level])) -> 38 | O17: =L17*N17 -> 4054.6 | P17: =(L17/SUM($L$8:$L$137))*$V$5 -> 269.245 | Q17: =O17-P17 -> 3785.355 | R17: =IF(Q17>0,Q17/$R$6,Q17) -> 5823.6231 | U17: Total Charge to HO: | V17: =SUM(V8:V16) -> #N/A
B18: Island Countertop | C18: Surface Type | D18: Surface Type | E18: Dallas White | F18: =VLOOKUP(E18,Counter_Pricing[[Material_Name]:[Level]],5,0) -> Level 1 | K18: 98 | L18: =K18*(1+$L$6) -> 107.8 | M18: SF | N18: =INDEX(Counter_Pricing[Olsen_Cost],MATCH(F18,Counter_Pricing[Level])) -> 38 | O18: =L18*N18 -> 4096.4 | P18: =(L18/SUM($L$8:$L$137))*$V$5 -> 272.02073 | Q18: =O18-P18 -> 3824.3793 | R18: =IF(Q18>0,Q18/$R$6,Q18) -> 5883.6604 | U18: *All pricing displayed on this page is subject to change at the sole discression of Olsen Custom Homes. Pricing will be finalized via a customer option form.* | X18: Instructions for DESIGNER (During HO Meeting)
B19: Countertop | C19: Surface Type | D19: Surface Type | E19: Dallas White | F19: =VLOOKUP(E19,Counter_Pricing[[Material_Name]:[Level]],5,0) -> Level 1 | K19: 99 | L19: =K19*(1+$L$6) -> 108.9 | M19: SF | N19: =INDEX(Counter_Pricing[Olsen_Cost],MATCH(F19,Counter_Pricing[Level])) -> 38 | O19: =L19*N19 -> 4138.2 | P19: =(L19/SUM($L$8:$L$137))*$V$5 -> 274.79645 | Q19: =O19-P19 -> 3863.4036 | R19: =IF(Q19>0,Q19/$R$6,Q19) -> 5943.6978 | X19: Step #1: Select Type of Tile in Column C
B20: Countertop | C20: Surface Type | D20: Surface Type | E20: Dallas White | F20: =VLOOKUP(E20,Counter_Pricing[[Material_Name]:[Level]],5,0) -> Level 1 | K20: 100 | L20: =K20*(1+$L$6) -> 110 | M20: SF | N20: =INDEX(Counter_Pricing[Olsen_Cost],MATCH(F20,Counter_Pricing[Level])) -> 38 | O20: =L20*N20 -> 4180 | P20: =(L20/SUM($L$8:$L$137))*$V$5 -> 277.57217 | Q20: =O20-P20 -> 3902.4278 | R20: =IF(Q20>0,Q20/$R$6,Q20) -> 6003.7351 | X20: Step #2: Select Level of Tile in Column D
B21: Countertop | C21: Surface Type | D21: Surface Type | E21: Dallas White | F21: =VLOOKUP(E21,Counter_Pricing[[Material_Name]:[Level]],5,0) -> Level 1 | K21: 101 | L21: =K21*(1+$L$6) -> 111.1 | M21: SF | N21: =INDEX(Counter_Pricing[Olsen_Cost],MATCH(F21,Counter_Pricing[Level])) -> 38 | O21: =L21*N21 -> 4221.8 | P21: =(L21/SUM($L$8:$L$137))*$V$5 -> 280.34789 | Q21: =O21-P21 -> 3941.4521 | R21: =IF(Q21>0,Q21/$R$6,Q21) -> 6063.7725 | X21: Step #3: Select Product Name in Column E
X22: Step $4: Select Finish, Pattern, Direction, Grout and Joint
X23: Step #5: Input Niche width and height (=0 if no niche)
X24: Step #6: Add special instructions and notes
O25: *HO Pays: | R25: =SUM(R8:R24) -> 45055.758 | X25: Step #7: Explain to client this pricing is a ballpark price
B26: Master Bathroom | X26: Step #8: Verify ALL lines with SF value also have selection before pricing!!
B27: Countertop #1 | C27: Countertop Surface | D27: Surface Type | E27: Dallas White | F27: =VLOOKUP(E27,Counter_Pricing[[Material_Name]:[Level]],5,0) -> Level 1 | K27: 92 | L27: =K27*(1+$L$6) -> 101.2 | M27: SF | N27: =INDEX(Counter_Pricing[Olsen_Cost],MATCH(F27,Counter_Pricing[Level])) -> 38 | O27: =L27*N27 -> 3845.6 | P27: =(L27/SUM($L$8:$L$136))*$V$5 -> 255.3664 | Q27: =O27-P27 -> 3590.2336 | R27: =IF(Q27>0,Q27/$R$6,Q27) -> 5523.4363 | X27: Step #9: Add thin info and pricing to buildertrend and get a signoff
B28: Countertop #1 | C28: Edge Type | D28: Eased Edge | E28: Eased Edge | F28: =VLOOKUP(E28,Counter_Pricing[[Material_Name]:[Level]],5,0) -> Labor | K28: 93 | L28: =K28*(1+$L$6) -> 102.3 | M28: LF | N28: =INDEX(Counter_Pricing[Olsen_Cost],MATCH(F28,Counter_Pricing[Level])) -> 0 | O28: =L28*N28 -> 0 | P28: =(L28/SUM($L$8:$L$136))*$V$5 -> 258.14212 | Q28: =O28-P28 -> -258.14212 | R28: =IF(Q28>0,Q28/$R$6,Q28) -> -258.14212 | X28: Step #10: Add correct language to the COF and total charge to HO (Cell V17)
B29: Countertop #1 | C29: Cutout | D29: Sink (Undermount) | E29: Sink Cutout | F29: =VLOOKUP(E29,Counter_Pricing[[Material_Name]:[Level]],5,0) -> Labor | K29: 94 | L29: =K29*(1+$L$6) -> 103.4 | M29: SF | N29: =INDEX(Counter_Pricing[Olsen_Cost],MATCH(F29,Counter_Pricing[Level])) -> 0 | O29: =L29*N29 -> 0 | P29: =(L29/SUM($L$8:$L$136))*$V$5 -> 260.91784 | Q29: =O29-P29 -> -260.91784 | R29: =IF(Q29>0,Q29/$R$6,Q29) -> -260.91784
B30: Countertop #2 | C30: Countertop Surface | D30: Surface Type | E30: Dallas White | F30: =VLOOKUP(E30,Counter_Pricing[[Material_Name]:[Level]],5,0) -> Level 1 | K30: 95 | L30: =K30*(1+$L$6) -> 104.5 | M30: SF | N30: =INDEX(Counter_Pricing[Olsen_Cost],MATCH(F30,Counter_Pricing[Level])) -> 38 | O30: =L30*N30 -> 3971 | P30: =(L30/SUM($L$8:$L$136))*$V$5 -> 263.69356 | Q30: =O30-P30 -> 3707.3064 | R30: =IF(Q30>0,Q30/$R$6,Q30) -> 5703.5484
B31: Countertop #2 | C31: Edge Type | D31: Mitered Edge | E31: Mitered Edge | F31: =VLOOKUP(E31,Counter_Pricing[[Material_Name]:[Level]],5,0) -> Labor | K31: 96 | L31: =K31*(1+$L$6) -> 105.6 | M31: SF | N31: =INDEX(Counter_Pricing[Olsen_Cost],MATCH(F31,Counter_Pricing[Level])) -> 0 | O31: =L31*N31 -> 0 | P31: =(L31/SUM($L$8:$L$136))*$V$5 -> 266.46928 | Q31: =O31-P31 -> -266.46928 | R31: =IF(Q31>0,Q31/$R$6,Q31) -> -266.46928
B32: Countertop #2 | C32: Cutout | D32: Cooktop | E32: Sink Cutout | F32: =VLOOKUP(E32,Counter_Pricing[[Material_Name]:[Level]],5,0) -> Labor | K32: 97 | L32: =K32*(1+$L$6) -> 106.7 | M32: SF | N32: =INDEX(Counter_Pricing[Olsen_Cost],MATCH(F32,Counter_Pricing[Level])) -> 0 | O32: =L32*N32 -> 0 | P32: =(L32/SUM($L$8:$L$136))*$V$5 -> 269.245 | Q32: =O32-P32 -> -269.245 | R32: =IF(Q32>0,Q32/$R$6,Q32) -> -269.245
B33: Countertop #2 | C33: Cutout | D33: Sink (Undermount) | E33: Sink Cutout | F33: =VLOOKUP(E33,Counter_Pricing[[Material_Name]:[Level]],5,0) -> Labor | K33: 98 | L33: =K33*(1+$L$6) -> 107.8 | M33: SF | N33: =INDEX(Counter_Pricing[Olsen_Cost],MATCH(F33,Counter_Pricing[Level])) -> 0 | O33: =L33*N33 -> 0 | P33: =(L33/SUM($L$8:$L$136))*$V$5 -> 272.02073 | Q33: =O33-P33 -> -272.02073 | R33: =IF(Q33>0,Q33/$R$6,Q33) -> -272.02073 | X33: Instructions for ESTIMATOR (After-HO meeting)
B34: Island Countertop | C34: Countertop Surface | D34: Surface Type | E34: Dallas White | F34: =VLOOKUP(E34,Counter_Pricing[[Material_Name]:[Level]],5,0) -> Level 1 | K34: 95 | L34: =K34*(1+$L$6) -> 104.5 | M34: SF | N34: =INDEX(Counter_Pricing[Olsen_Cost],MATCH(F34,Counter_Pricing[Level])) -> 38 | O34: =L34*N34 -> 3971 | P34: =(L34/SUM($L$8:$L$136))*$V$5 -> 263.69356 | Q34: =O34-P34 -> 3707.3064 | R34: =IF(Q34>0,Q34/$R$6,Q34) -> 5703.5484 | X34: Step #1: Verify Pricing
B35: Island Countertop | C35: Edge Type | D35: Eased Edge | E35: Eased Edge | F35: =VLOOKUP(E35,Counter_Pricing[[Material_Name]:[Level]],5,0) -> Labor | K35: 96 | L35: =K35*(1+$L$6) -> 105.6 | M35: SF | N35: =INDEX(Counter_Pricing[Olsen_Cost],MATCH(F35,Counter_Pricing[Level])) -> 0 | O35: =L35*N35 -> 0 | P35: =(L35/SUM($L$8:$L$136))*$V$5 -> 266.46928 | Q35: =O35-P35 -> -266.46928 | R35: =IF(Q35>0,Q35/$R$6,Q35) -> -266.46928 | X35: Step #2: Assign all Rooms in Rows 8, 29,42, 55,68,81,94,107,120
B36: Island Countertop | C36: Waterfall Surface | D36: Surface Type | E36: Dallas White | F36: =VLOOKUP(E36,Counter_Pricing[[Material_Name]:[Level]],5,0) -> Level 1 | H36: Left Waterfall | K36: 97 | L36: =K36*(1+$L$6) -> 106.7 | M36: SF | N36: =INDEX(Counter_Pricing[Olsen_Cost],MATCH(F36,Counter_Pricing[Level])) -> 38 | O36: =L36*N36 -> 4054.6 | P36: =(L36/SUM($L$8:$L$136))*$V$5 -> 269.245 | Q36: =O36-P36 -> 3785.355 | R36: =IF(Q36>0,Q36/$R$6,Q36) -> 5823.6231 | X36: Step #3: Assign all areas receiving tile Column B
B37: Island Countertop | C37: Surface Type | D37: Surface Type | E37: Dallas White | F37: =VLOOKUP(E37,Counter_Pricing[[Material_Name]:[Level]],5,0) -> Level 1 | K37: 98 | L37: =K37*(1+$L$6) -> 107.8 | M37: SF | N37: =INDEX(Counter_Pricing[Olsen_Cost],MATCH(F37,Counter_Pricing[Level])) -> 38 | O37: =L37*N37 -> 4096.4 | P37: =(L37/SUM($L$8:$L$136))*$V$5 -> 272.02073 | Q37: =O37-P37 -> 3824.3793 | R37: =IF(Q37>0,Q37/$R$6,Q37) -> 5883.6604
B38: Countertop | C38: Surface Type | D38: Surface Type | E38: Dallas White | F38: =VLOOKUP(E38,Counter_Pricing[[Material_Name]:[Level]],5,0) -> Level 1 | K38: 99 | L38: =K38*(1+$L$6) -> 108.9 | M38: SF | N38: =INDEX(Counter_Pricing[Olsen_Cost],MATCH(F38,Counter_Pricing[Level])) -> 38 | O38: =L38*N38 -> 4138.2 | P38: =(L38/SUM($L$8:$L$136))*$V$5 -> 274.79645 | Q38: =O38-P38 -> 3863.4036 | R38: =IF(Q38>0,Q38/$R$6,Q38) -> 5943.6978
B39: Countertop | C39: Surface Type | D39: Surface Type | E39: Dallas White | F39: =VLOOKUP(E39,Counter_Pricing[[Material_Name]:[Level]],5,0) -> Level 1 | K39: 100 | L39: =K39*(1+$L$6) -> 110 | M39: SF | N39: =INDEX(Counter_Pricing[Olsen_Cost],MATCH(F39,Counter_Pricing[Level])) -> 38 | O39: =L39*N39 -> 4180 | P39: =(L39/SUM($L$8:$L$136))*$V$5 -> 277.57217 | Q39: =O39-P39 -> 3902.4278 | R39: =IF(Q39>0,Q39/$R$6,Q39) -> 6003.7351
C40: Surface Type | D40: Surface Type | E40: Dallas White | F40: =VLOOKUP(E40,Counter_Pricing[[Material_Name]:[Level]],5,0) -> Level 1 | K40: 101 | L40: =K40*(1+$L$6) -> 111.1 | M40: SF | N40: =INDEX(Counter_Pricing[Olsen_Cost],MATCH(F40,Counter_Pricing[Level])) -> 38 | O40: =L40*N40 -> 4221.8 | P40: =(L40/SUM($L$8:$L$136))*$V$5 -> 280.34789 | Q40: =O40-P40 -> 3941.4521 | R40: =IF(Q40>0,Q40/$R$6,Q40) -> 6063.7725
O41: *HO Pays: | R41: =SUM(R27:R40) -> 45055.758
...

Sheet Tile-Floor
B2: Tile Quick Pricing Sheet | L2: ='Customer Option Cover Page'!C6 -> John Doe
B3: =U18 -> *All pricing displayed on this page is subject to change at the sole discression of Olsen Custom Homes. Pricing will be finalized via a customer option form.* | L3: ='Customer Option Cover Page'!C7 -> 123 avenue
B4: Designer Information | L4: Estimator | U4: Summary | X4: Instructions
B5: Area/Room | C5: Type | D5: Level | E5: Product Name | F5: Notes | G5: Finish | H5: Pattern | I5: Direction | J5: Grout | K5: Joint | L5: Qty_Est | M5: Qty_Pad | N5: Units | O5: $ / Unit | P5: Olsen Total | Q5: Included | R5: Difference | S5: Charge HO | U5: Allowance Total: | V5: 30000 | X5: **Please read this and follow the process EXACTLY**
M6: 0.1 | S6: 0.65 | X6: Instructions for ESTIMATOR
B7: Main Flooring Selections | U7: Area | V7: Charge to HO | X7: Instructions for ESTIMATOR (BEFORE-HO meeting)
B8: Foyer | C8: Floor Tile | D8: Level 4 | E8: Dublin- 13"x13" Straight (no offset) | L8: 1680.7 | M8: =L8*(1+$M$6) -> 1848.77 | N8: SF | O8: =IF(AND($C8<>"",$D8<>"",$E8<>""),IF(COUNTIFS(TileTable[Section],$C8,TileTable[Level],$D8,TileTable[Item_Name],$E8)>0,SUMIFS(TileTable[Olsen_Cost],TileTable[Section],$C8,TileTable[Level],$D8,TileTable[Item_Name],$E8),""),"0") -> 7 | P8: =O8*M8 -> 12941.39 | Q8: =(M8/SUM($M$8:$M$30,$M$32:$M$43,$M$45:$M$56,$M$58:$M$69,$M$71:$M$82,$M$84:$M$95,$M$97:$M$108,$M$110:$M$121,$M$123:$M$134))*$V$5 -> 29773.641 | R8: =P8-Q8 -> -16832.251 | S8: =IF(R8>0,R8/$S$6,R8) -> -16832.251 | U8: =B7 -> Main Flooring Selections | V8: =S30 -> -16849.352 | X8: Step #1: Input correct allowance total in cell V5
B9: Family Room | C9: Listel | D9: Level 2 | E9: Autumn Mist Random Linear Glass Mosaic - 4x12" listel - (1/3 sheet) | M9: =L9*(1+$M$6) -> 0 | N9: SF | O9: =IF(AND($C9<>"",$D9<>"",$E9<>""),IF(COUNTIFS(TileTable[Section],$C9,TileTable[Level],$D9,TileTable[Item_Name],$E9)>0,SUMIFS(TileTable[Olsen_Cost],TileTable[Section],$C9,TileTable[Level],$D9,TileTable[Item_Name],$E9),""),"0") -> 10.47 | P9: =O9*M9 -> 0 | Q9: =(M9/SUM($M$8:$M$30,$M$32:$M$43,$M$45:$M$56,$M$58:$M$69,$M$71:$M$82,$M$84:$M$95,$M$97:$M$108,$M$110:$M$121,$M$123:$M$134))*$V$5 -> 0 | R9: =P9-Q9 -> 0 | S9: =IF(R9>0,R9/$S$6,R9) -> 0 | U9: =B31 -> Master Bathroom | V9: =S43 -> -49.208401 | X9: Step #2: Assign all Rooms in BLACK Rows (7, 31,44, 57,70,83,96,109,122)
B10: Kitchen/Nook | C10: Carpet | D10: Level 1 | M10: =L10*(1+$M$6) -> 0 | N10: SF | O10: =IF(AND($C10<>"",$D10<>"",$E10<>""),IF(COUNTIFS(TileTable[Section],$C10,TileTable[Level],$D10,TileTable[Item_Name],$E10)>0,SUMIFS(TileTable[Olsen_Cost],TileTable[Section],$C10,TileTable[Level],$D10,TileTable[Item_Name],$E10),""),"0") -> 0 | P10: =O10*M10 -> 0 | Q10: =(M10/SUM($M$8:$M$30,$M$32:$M$43,$M$45:$M$56,$M$58:$M$69,$M$71:$M$82,$M$84:$M$95,$M$97:$M$108,$M$110:$M$121,$M$123:$M$134))*$V$5 -> 0 | R10: =P10-Q10 -> 0 | S10: =IF(R10>0,R10/$S$6,R10) -> 0 | U10: =B44 -> Bathroom #2 | V10: =S56 -> 0 | X10: Step #3: Assign all areas receiving tile Column B
B11: Pantry | C11: Shower / Tub Wall Tile | M11: =L11*(1+$M$6) -> 0 | N11: SF | O11: =IF(AND($C11<>"",$D11<>"",$E11<>""),IF(COUNTIFS(TileTable[Section],$C11,TileTable[Level],$D11,TileTable[Item_Name],$E11)>0,SUMIFS(TileTable[Olsen_Cost],TileTable[Section],$C11,TileTable[Level],$D11,TileTable[Item_Name],$E11),""),"0") -> 0 | P11: =O11*M11 -> 0 | Q11: =(M11/SUM($M$8:$M$30,$M$32:$M$43,$M$45:$M$56,$M$58:$M$69,$M$71:$M$82,$M$84:$M$95,$M$97:$M$108,$M$110:$M$121,$M$123:$M$134))*$V$5 -> 0 | R11: =P11-Q11 -> 0 | S11: =IF(R11>0,R11/$S$6,R11) -> 0 | U11: =B57 -> Bathroom #3 | V11: =S69 -> 0 | X11: Step #4: Input each square footage estimate in Column L
B12: Laundry Room | C12: Wood | D12: Level 1 | E12: Essence | L12: 10 | M12: =L12*(1+$M$6) -> 11 | N12: SF | O12: =IF(AND($C12<>"",$D12<>"",$E12<>""),IF(COUNTIFS(TileTable[Section],$C12,TileTable[Level],$D12,TileTable[Item_Name],$E12)>0,SUMIFS(TileTable[Olsen_Cost],TileTable[Section],$C12,TileTable[Level],$D12,TileTable[Item_Name],$E12),""),"0") -> 14.55 | P12: =O12*M12 -> 160.05 | Q12: =(M12/SUM($M$8:$M$30,$M$32:$M$43,$M$45:$M$56,$M$58:$M$69,$M$71:$M$82,$M$84:$M$95,$M$97:$M$108,$M$110:$M$121,$M$123:$M$134))*$V$5 -> 177.15024 | R12: =P12-Q12 -> -17.100243 | S12: =IF(R12>0,R12/$S$6,R12) -> -17.100243 | U12: =B70 -> Bathroom #4 | V12: =S82 -> 0 | X12: Step #5: Hide Columns L, Q, and R (highlighted in red)
B13: Hallways | C13: Floor Tile | M13: =L13*(1+$M$6) -> 0 | N13: SF | O13: =IF(AND($C13<>"",$D13<>"",$E13<>""),IF(COUNTIFS(TileTable[Section],$C13,TileTable[Level],$D13,TileTable[Item_Name],$E13)>0,SUMIFS(TileTable[Olsen_Cost],TileTable[Section],$C13,TileTable[Level],$D13,TileTable[Item_Name],$E13),""),"0") -> 0 | P13: =O13*M13 -> 0 | Q13: =(M13/SUM($M$8:$M$30,$M$32:$M$43,$M$45:$M$56,$M$58:$M$69,$M$71:$M$82,$M$84:$M$95,$M$97:$M$108,$M$110:$M$121,$M$123:$M$134))*$V$5 -> 0 | R13: =P13-Q13 -> 0 | S13: =IF(R13>0,R13/$S$6,R13) -> 0 | U13: =B83 -> Bathroom #5 | V13: =S95 -> 0 | X13: Step #6: Verify Pricing is correct at bottom of sheet
B14: Master Suite | C14: Floor Tile | M14: =L14*(1+$M$6) -> 0 | N14: SF | O14: =IF(AND($C14<>"",$D14<>"",$E14<>""),IF(COUNTIFS(TileTable[Section],$C14,TileTable[Level],$D14,TileTable[Item_Name],$E14)>0,SUMIFS(TileTable[Olsen_Cost],TileTable[Section],$C14,TileTable[Level],$D14,TileTable[Item_Name],$E14),""),"0") -> 0 | P14: =O14*M14 -> 0 | Q14: =(M14/SUM($M$8:$M$30,$M$32:$M$43,$M$45:$M$56,$M$58:$M$69,$M$71:$M$82,$M$84:$M$95,$M$97:$M$108,$M$110:$M$121,$M$123:$M$134))*$V$5 -> 0 | R14: =P14-Q14 -> 0 | S14: =IF(R14>0,R14/$S$6,R14) -> 0 | U14: =B96 -> Bathroom #6 | V14: =S108 -> 0 | X14: Instructions for DESIGNER (BEFORE HO Meeting)
B15: Master Closet | C15: Floor Tile | M15: =L15*(1+$M$6) -> 0 | N15: SF | O15: =IF(AND($C15<>"",$D15<>"",$E15<>""),IF(COUNTIFS(TileTable[Section],$C15,TileTable[Level],$D15,TileTable[Item_Name],$E15)>0,SUMIFS(TileTable[Olsen_Cost],TileTable[Section],$C15,TileTable[Level],$D15,TileTable[Item_Name],$E15),""),"0") -> 0 | P15: =O15*M15 -> 0 | Q15: =(M15/SUM($M$8:$M$30,$M$32:$M$43,$M$45:$M$56,$M$58:$M$69,$M$71:$M$82,$M$84:$M$95,$M$97:$M$108,$M$110:$M$121,$M$123:$M$134))*$V$5 -> 0 | R15: =P15-Q15 -> 0 | S15: =IF(R15>0,R15/$S$6,R15) -> 0 | U15: =B109 -> Backsplash | V15: =S121 -> 0 | X15: Step #1: Input any selections from BT if client has already made them
B16: Master Bathroom | C16: Floor Tile | M16: =L16*(1+$M$6) -> 0 | N16: SF | O16: =IF(AND($C16<>"",$D16<>"",$E16<>""),IF(COUNTIFS(TileTable[Section],$C16,TileTable[Level],$D16,TileTable[Item_Name],$E16)>0,SUMIFS(TileTable[Olsen_Cost],TileTable[Section],$C16,TileTable[Level],$D16,TileTable[Item_Name],$E16),""),"0") -> 0 | P16: =O16*M16 -> 0 | Q16: =(M16/SUM($M$8:$M$30,$M$32:$M$43,$M$45:$M$56,$M$58:$M$69,$M$71:$M$82,$M$84:$M$95,$M$97:$M$108,$M$110:$M$121,$M$123:$M$134))*$V$5 -> 0 | R16: =P16-Q16 -> 0 | S16: =IF(R16>0,R16/$S$6,R16) -> 0 | U16: =B122 -> Fireplace | V16: =S134 -> 0 | X16: Step #2: Verify Estimator has input ALL area information in Column L
B17: Bedroom #2 | C17: Floor Tile | M17: =L17*(1+$M$6) -> 0 | N17: SF | O17: =IF(AND($C17<>"",$D17<>"",$E17<>""),IF(COUNTIFS(TileTable[Section],$C17,TileTable[Level],$D17,TileTable[Item_Name],$E17)>0,SUMIFS(TileTable[Olsen_Cost],TileTable[Section],$C17,TileTable[Level],$D17,TileTable[Item_Name],$E17),""),"0") -> 0 | P17: =O17*M17 -> 0 | Q17: =(M17/SUM($M$8:$M$30,$M$32:$M$43,$M$45:$M$56,$M$58:$M$69,$M$71:$M$82,$M$84:$M$95,$M$97:$M$108,$M$110:$M$121,$M$123:$M$134))*$V$5 -> 0 | R17: =P17-Q17 -> 0 | S17: =IF(R17>0,R17/$S$6,R17) -> 0 | U17: Total Charge to HO: | V17: =SUM(V8:V16) -> -16898.56
B18: Bedroom #3 | C18: Floor Tile | M18: =L18*(1+$M$6) -> 0 | N18: SF | O18: =IF(AND($C18<>"",$D18<>"",$E18<>""),IF(COUNTIFS(TileTable[Section],$C18,TileTable[Level],$D18,TileTable[Item_Name],$E18)>0,SUMIFS(TileTable[Olsen_Cost],TileTable[Section],$C18,TileTable[Level],$D18,TileTable[Item_Name],$E18),""),"0") -> 0 | P18: =O18*M18 -> 0 | Q18: =(M18/SUM($M$8:$M$30,$M$32:$M$43,$M$45:$M$56,$M$58:$M$69,$M$71:$M$82,$M$84:$M$95,$M$97:$M$108,$M$110:$M$121,$M$123:$M$134))*$V$5 -> 0 | R18: =P18-Q18 -> 0 | S18: =IF(R18>0,R18/$S$6,R18) -> 0 | U18: *All pricing displayed on this page is subject to change at the sole discression of Olsen Custom Homes. Pricing will be finalized via a customer option form.* | X18: Instructions for DESIGNER (During HO Meeting)
B19: Bedroom #4 | C19: Floor Tile | M19: =L19*(1+$M$6) -> 0 | N19: SF | O19: =IF(AND($C19<>"",$D19<>"",$E19<>""),IF(COUNTIFS(TileTable[Section],$C19,TileTable[Level],$D19,TileTable[Item_Name],$E19)>0,SUMIFS(TileTable[Olsen_Cost],TileTable[Section],$C19,TileTable[Level],$D19,TileTable[Item_Name],$E19),""),"0") -> 0 | P19: =O19*M19 -> 0 | Q19: =(M19/SUM($M$8:$M$30,$M$32:$M$43,$M$45:$M$56,$M$58:$M$69,$M$71:$M$82,$M$84:$M$95,$M$97:$M$108,$M$110:$M$121,$M$123:$M$134))*$V$5 -> 0 | R19: =P19-Q19 -> 0 | S19: =IF(R19>0,R19/$S$6,R19) -> 0 | X19: Step #1: Select Type of Tile in Column C
B20: Bedroom #5 | C20: Floor Tile | M20: =L20*(1+$M$6) -> 0 | N20: SF | O20: =IF(AND($C20<>"",$D20<>"",$E20<>""),IF(COUNTIFS(TileTable[Section],$C20,TileTable[Level],$D20,TileTable[Item_Name],$E20)>0,SUMIFS(TileTable[Olsen_Cost],TileTable[Section],$C20,TileTable[Level],$D20,TileTable[Item_Name],$E20),""),"0") -> 0 | P20: =O20*M20 -> 0 | Q20: =(M20/SUM($M$8:$M$30,$M$32:$M$43,$M$45:$M$56,$M$58:$M$69,$M$71:$M$82,$M$84:$M$95,$M$97:$M$108,$M$110:$M$121,$M$123:$M$134))*$V$5 -> 0 | R20: =P20-Q20 -> 0 | S20: =IF(R20>0,R20/$S$6,R20) -> 0 | X20: Step #2: Select Level of Tile in Column D
B21: Bedroom #6 | C21: Floor Tile | M21: =L21*(1+$M$6) -> 0 | N21: SF | O21: =IF(AND($C21<>"",$D21<>"",$E21<>""),IF(COUNTIFS(TileTable[Section],$C21,TileTable[Level],$D21,TileTable[Item_Name],$E21)>0,SUMIFS(TileTable[Olsen_Cost],TileTable[Section],$C21,TileTable[Level],$D21,TileTable[Item_Name],$E21),""),"0") -> 0 | P21: =O21*M21 -> 0 | Q21: =(M21/SUM($M$8:$M$30,$M$32:$M$43,$M$45:$M$56,$M$58:$M$69,$M$71:$M$82,$M$84:$M$95,$M$97:$M$108,$M$110:$M$121,$M$123:$M$134))*$V$5 -> 0 | R21: =P21-Q21 -> 0 | S21: =IF(R21>0,R21/$S$6,R21) -> 0 | X21: Step #3: Select Product Name in Column E
B22: Bathroom #2 | C22: Floor Tile | M22: =L22*(1+$M$6) -> 0 | N22: SF | O22: =IF(AND($C22<>"",$D22<>"",$E22<>""),IF(COUNTIFS(TileTable[Section],$C22,TileTable[Level],$D22,TileTable[Item_Name],$E22)>0,SUMIFS(TileTable[Olsen_Cost],TileTable[Section],$C22,TileTable[Level],$D22,TileTable[Item_Name],$E22),""),"0") -> 0 | P22: =O22*M22 -> 0 | Q22: =(M22/SUM($M$8:$M$30,$M$32:$M$43,$M$45:$M$56,$M$58:$M$69,$M$71:$M$82,$M$84:$M$95,$M$97:$M$108,$M$110:$M$121,$M$123:$M$134))*$V$5 -> 0 | R22: =P22-Q22 -> 0 | S22: =IF(R22>0,R22/$S$6,R22) -> 0 | X22: Step $4: Select Finish, Pattern, Direction, Grout and Joint
B23: Bathroom #3 | C23: Floor Tile | M23: =L23*(1+$M$6) -> 0 | N23: SF | O23: =IF(AND($C23<>"",$D23<>"",$E23<>""),IF(COUNTIFS(TileTable[Section],$C23,TileTable[Level],$D23,TileTable[Item_Name],$E23)>0,SUMIFS(TileTable[Olsen_Cost],TileTable[Section],$C23,TileTable[Level],$D23,TileTable[Item_Name],$E23),""),"0") -> 0 | P23: =O23*M23 -> 0 | Q23: =(M23/SUM($M$8:$M$30,$M$32:$M$43,$M$45:$M$56,$M$58:$M$69,$M$71:$M$82,$M$84:$M$95,$M$97:$M$108,$M$110:$M$121,$M$123:$M$134))*$V$5 -> 0 | R23: =P23-Q23 -> 0 | S23: =IF(R23>0,R23/$S$6,R23) -> 0 | X23: Step #5: Input Niche width and height (=0 if no niche)
B24: Bathroom #4 | C24: Floor Tile | M24: =L24*(1+$M$6) -> 0 | N24: SF | O24: =IF(AND($C24<>"",$D24<>"",$E24<>""),IF(COUNTIFS(TileTable[Section],$C24,TileTable[Level],$D24,TileTable[Item_Name],$E24)>0,SUMIFS(TileTable[Olsen_Cost],TileTable[Section],$C24,TileTable[Level],$D24,TileTable[Item_Name],$E24),""),"0") -> 0 | P24: =O24*M24 -> 0 | Q24: =(M24/SUM($M$8:$M$30,$M$32:$M$43,$M$45:$M$56,$M$58:$M$69,$M$71:$M$82,$M$84:$M$95,$M$97:$M$108,$M$110:$M$121,$M$123:$M$134))*$V$5 -> 0 | R24: =P24-Q24 -> 0 | S24: =IF(R24>0,R24/$S$6,R24) -> 0 | X24: Step #6: Add special instructions and notes
B25: Bathroom #5 | C25: Floor Tile | M25: =L25*(1+$M$6) -> 0 | N25: SF | O25: =IF(AND($C25<>"",$D25<>"",$E25<>""),IF(COUNTIFS(TileTable[Section],$C25,TileTable[Level],$D25,TileTable[Item_Name],$E25)>0,SUMIFS(TileTable[Olsen_Cost],TileTable[Section],$C25,TileTable[Level],$D25,TileTable[Item_Name],$E25),""),"0") -> 0 | P25: =O25*M25 -> 0 | Q25: =(M25/SUM($M$8:$M$30,$M$32:$M$43,$M$45:$M$56,$M$58:$M$69,$M$71:$M$82,$M$84:$M$95,$M$97:$M$108,$M$110:$M$121,$M$123:$M$134))*$V$5 -> 0 | R25: =P25-Q25 -> 0 | S25: =IF(R25>0,R25/$S$6,R25) -> 0 | X25: Step #7: Explain to client this pricing is a ballpark price
B26: Bathroom #6 | C26: Floor Tile | M26: =L26*(1+$M$6) -> 0 | N26: SF | O26: =IF(AND($C26<>"",$D26<>"",$E26<>""),IF(COUNTIFS(TileTable[Section],$C26,TileTable[Level],$D26,TileTable[Item_Name],$E26)>0,SUMIFS(TileTable[Olsen_Cost],TileTable[Section],$C26,TileTable[Level],$D26,TileTable[Item_Name],$E26),""),"0") -> 0 | P26: =O26*M26 -> 0 | Q26: =(M26/SUM($M$8:$M$30,$M$32:$M$43,$M$45:$M$56,$M$58:$M$69,$M$71:$M$82,$M$84:$M$95,$M$97:$M$108,$M$110:$M$121,$M$123:$M$134))*$V$5 -> 0 | R26: =P26-Q26 -> 0 | S26: =IF(R26>0,R26/$S$6,R26) -> 0 | X26: Step #8: Verify ALL lines with SF value also have selection before pricing!!
M27: =L27*(1+$M$6) -> 0 | N27: SF | O27: =IF(AND($C27<>"",$D27<>"",$E27<>""),IF(COUNTIFS(TileTable[Section],$C27,TileTable[Level],$D27,TileTable[Item_Name],$E27)>0,SUMIFS(TileTable[Olsen_Cost],TileTable[Section],$C27,TileTable[Level],$D27,TileTable[Item_Name],$E27),""),"0") -> 0 | P27: =O27*M27 -> 0 | Q27: =(M27/SUM($M$8:$M$30,$M$32:$M$43,$M$45:$M$56,$M$58:$M$69,$M$71:$M$82,$M$84:$M$95,$M$97:$M$108,$M$110:$M$121,$M$123:$M$134))*$V$5 -> 0 | R27: =P27-Q27 -> 0 | S27: =IF(R27>0,R27/$S$6,R27) -> 0 | X27: Step #9: Add thin info and pricing to buildertrend and get a signoff
M28: =L28*(1+$M$6) -> 0 | N28: SF | O28: =IF(AND($C28<>"",$D28<>"",$E28<>""),IF(COUNTIFS(TileTable[Section],$C28,TileTable[Level],$D28,TileTable[Item_Name],$E28)>0,SUMIFS(TileTable[Olsen_Cost],TileTable[Section],$C28,TileTable[Level],$D28,TileTable[Item_Name],$E28),""),"0") -> 0 | P28: =O28*M28 -> 0 | Q28: =(M28/SUM($M$8:$M$30,$M$32:$M$43,$M$45:$M$56,$M$58:$M$69,$M$71:$M$82,$M$84:$M$95,$M$97:$M$108,$M$110:$M$121,$M$123:$M$134))*$V$5 -> 0 | R28: =P28-Q28 -> 0 | S28: =IF(R28>0,R28/$S$6,R28) -> 0 | X28: Step #10: Add correct language to the COF and total charge to HO (Cell V17)
M29: =L29*(1+$M$6) -> 0 | N29: SF | O29: =IF(AND($C29<>"",$D29<>"",$E29<>""),IF(COUNTIFS(TileTable[Section],$C29,TileTable[Level],$D29,TileTable[Item_Name],$E29)>0,SUMIFS(TileTable[Olsen_Cost],TileTable[Section],$C29,TileTable[Level],$D29,TileTable[Item_Name],$E29),""),"0") -> 0 | P29: =O29*M29 -> 0 | Q29: =(M29/SUM($M$8:$M$30,$M$32:$M$43,$M$45:$M$56,$M$58:$M$69,$M$71:$M$82,$M$84:$M$95,$M$97:$M$108,$M$110:$M$121,$M$123:$M$134))*$V$5 -> 0 | R29: =P29-Q29 -> 0 | S29: =IF(R29>0,R29/$S$6,R29) -> 0
P30: *HO Pays: | S30: =SUM(S8:S29) -> -16849.352
B31: Master Bathroom
B32: Shower Floor Pan | C32: Shower Pan Tile | M32: =L32*(1+$M$6) -> 0 | N32: SF | O32: =IF(AND($C32<>"",$D32<>"",$E32<>""),IF(COUNTIFS(TileTable[Section],$C32,TileTable[Level],$D32,TileTable[Item_Name],$E32)>0,SUMIFS(TileTable[Olsen_Cost],TileTable[Section],$C32,TileTable[Level],$D32,TileTable[Item_Name],$E32),""),"0") -> 0 | P32: =O32*M32 -> 0 | Q32: =(M32/SUM($M$8:$M$30,$M$32:$M$43,$M$45:$M$56,$M$58:$M$69,$M$71:$M$82,$M$84:$M$95,$M$97:$M$108,$M$110:$M$121,$M$123:$M$134))*$V$5 -> 0 | R32: =P32-Q32 -> 0 | S32: =IF(R32>0,R32/$S$6,R32) -> 0
B33: Shower Walls (8') | C33: Shower / Tub Wall Tile | M33: =L33*(1+$M$6) -> 0 | N33: SF | O33: =IF(AND($C33<>"",$D33<>"",$E33<>""),IF(COUNTIFS(TileTable[Section],$C33,TileTable[Level],$D33,TileTable[Item_Name],$E33)>0,SUMIFS(TileTable[Olsen_Cost],TileTable[Section],$C33,TileTable[Level],$D33,TileTable[Item_Name],$E33),""),"0") -> 0 | P33: =O33*M33 -> 0 | Q33: =(M33/SUM($M$8:$M$30,$M$32:$M$43,$M$45:$M$56,$M$58:$M$69,$M$71:$M$82,$M$84:$M$95,$M$97:$M$108,$M$110:$M$121,$M$123:$M$134))*$V$5 -> 0 | R33: =P33-Q33 -> 0 | S33: =IF(R33>0,R33/$S$6,R33) -> 0 | X33: Instructions for ESTIMATOR (After-HO meeting)
B34: (+) Shower Walls to Ceiling | C34: Shower / Tub Wall Tile | M34: =L34*(1+$M$6) -> 0 | N34: SF | O34: =IF(AND($C34<>"",$D34<>"",$E34<>""),IF(COUNTIFS(TileTable[Section],$C34,TileTable[Level],$D34,TileTable[Item_Name],$E34)>0,SUMIFS(TileTable[Olsen_Cost],TileTable[Section],$C34,TileTable[Level],$D34,TileTable[Item_Name],$E34),""),"0") -> 0 | P34: =O34*M34 -> 0 | Q34: =(M34/SUM($M$8:$M$30,$M$32:$M$43,$M$45:$M$56,$M$58:$M$69,$M$71:$M$82,$M$84:$M$95,$M$97:$M$108,$M$110:$M$121,$M$123:$M$134))*$V$5 -> 0 | R34: =P34-Q34 -> 0 | S34: =IF(R34>0,R34/$S$6,R34) -> 0 | X34: Step #1: Verify Pricing
B35: Shower Niche | C35: Shower Pan Tile | L35: =G43 -> 2.7777778 | M35: =L35*(1+$M$6) -> 3.0555556 | N35: SF | O35: =IF(AND($C35<>"",$D35<>"",$E35<>""),IF(COUNTIFS(TileTable[Section],$C35,TileTable[Level],$D35,TileTable[Item_Name],$E35)>0,SUMIFS(TileTable[Olsen_Cost],TileTable[Section],$C35,TileTable[Level],$D35,TileTable[Item_Name],$E35),""),"0") -> 0 | P35: =O35*M35 -> 0 | Q35: =(M35/SUM($M$8:$M$30,$M$32:$M$43,$M$45:$M$56,$M$58:$M$69,$M$71:$M$82,$M$84:$M$95,$M$97:$M$108,$M$110:$M$121,$M$123:$M$134))*$V$5 -> 49.208401 | R35: =P35-Q35 -> -49.208401 | S35: =IF(R35>0,R35/$S$6,R35) -> -49.208401 | X35: Step #2: Assign all Rooms in Rows 8, 29,42, 55,68,81,94,107,120
B36: Knee Wall (Inside Shower Face) | M36: =L36*(1+$M$6) -> 0 | N36: SF | O36: =IF(AND($C36<>"",$D36<>"",$E36<>""),IF(COUNTIFS(TileTable[Section],$C36,TileTable[Level],$D36,TileTable[Item_Name],$E36)>0,SUMIFS(TileTable[Olsen_Cost],TileTable[Section],$C36,TileTable[Level],$D36,TileTable[Item_Name],$E36),""),"0") -> 0 | P36: =O36*M36 -> 0 | Q36: =(M36/SUM($M$8:$M$30,$M$32:$M$43,$M$45:$M$56,$M$58:$M$69,$M$71:$M$82,$M$84:$M$95,$M$97:$M$108,$M$110:$M$121,$M$123:$M$134))*$V$5 -> 0 | R36: =P36-Q36 -> 0 | S36: =IF(R36>0,R36/$S$6,R36) -> 0 | X36: Step #3: Assign all areas receiving tile Column B
B37: Knee Wall (Outside Shower Face) | M37: =L37*(1+$M$6) -> 0 | N37: SF | O37: =IF(AND($C37<>"",$D37<>"",$E37<>""),IF(COUNTIFS(TileTable[Section],$C37,TileTable[Level],$D37,TileTable[Item_Name],$E37)>0,SUMIFS(TileTable[Olsen_Cost],TileTable[Section],$C37,TileTable[Level],$D37,TileTable[Item_Name],$E37),""),"0") -> 0 | P37: =O37*M37 -> 0 | Q37: =(M37/SUM($M$8:$M$30,$M$32:$M$43,$M$45:$M$56,$M$58:$M$69,$M$71:$M$82,$M$84:$M$95,$M$97:$M$108,$M$110:$M$121,$M$123:$M$134))*$V$5 -> 0 | R37: =P37-Q37 -> 0 | S37: =IF(R37>0,R37/$S$6,R37) -> 0
B38: Knee Wall Cap | C38: Knee Wall Cap | D38: Level 1 | M38: =L38*(1+$M$6) -> 0 | N38: SF | O38: =IF(AND($C38<>"",$D38<>"",$E38<>""),IF(COUNTIFS(TileTable[Section],$C38,TileTable[Level],$D38,TileTable[Item_Name],$E38)>0,SUMIFS(TileTable[Olsen_Cost],TileTable[Section],$C38,TileTable[Level],$D38,TileTable[Item_Name],$E38),""),"0") -> 0 | P38: =O38*M38 -> 0 | Q38: =(M38/SUM($M$8:$M$30,$M$32:$M$43,$M$45:$M$56,$M$58:$M$69,$M$71:$M$82,$M$84:$M$95,$M$97:$M$108,$M$110:$M$121,$M$123:$M$134))*$V$5 -> 0 | R38: =P38-Q38 -> 0 | S38: =IF(R38>0,R38/$S$6,R38) -> 0
B39: Sill | C39: Sill | D39: Level 1 | M39: =L39*(1+$M$6) -> 0 | N39: SF | O39: =IF(AND($C39<>"",$D39<>"",$E39<>""),IF(COUNTIFS(TileTable[Section],$C39,TileTable[Level],$D39,TileTable[Item_Name],$E39)>0,SUMIFS(TileTable[Olsen_Cost],TileTable[Section],$C39,TileTable[Level],$D39,TileTable[Item_Name],$E39),""),"0") -> 0 | P39: =O39*M39 -> 0 | Q39: =(M39/SUM($M$8:$M$30,$M$32:$M$43,$M$45:$M$56,$M$58:$M$69,$M$71:$M$82,$M$84:$M$95,$M$97:$M$108,$M$110:$M$121,$M$123:$M$134))*$V$5 -> 0 | R39: =P39-Q39 -> 0 | S39: =IF(R39>0,R39/$S$6,R39) -> 0
B40: Curb | C40: Curb | D40: Level 1 | M40: =L40*(1+$M$6) -> 0 | N40: SF | O40: =IF(AND($C40<>"",$D40<>"",$E40<>""),IF(COUNTIFS(TileTable[Section],$C40,TileTable[Level],$D40,TileTable[Item_Name],$E40)>0,SUMIFS(TileTable[Olsen_Cost],TileTable[Section],$C40,TileTable[Level],$D40,TileTable[Item_Name],$E40),""),"0") -> 0 | P40: =O40*M40 -> 0 | Q40: =(M40/SUM($M$8:$M$30,$M$32:$M$43,$M$45:$M$56,$M$58:$M$69,$M$71:$M$82,$M$84:$M$95,$M$97:$M$108,$M$110:$M$121,$M$123:$M$134))*$V$5 -> 0 | R40: =P40-Q40 -> 0 | S40: =IF(R40>0,R40/$S$6,R40) -> 0
M41: =L41*(1+$M$6) -> 0 | N41: SF | O41: =IF(AND($C41<>"",$D41<>"",$E41<>""),IF(COUNTIFS(TileTable[Section],$C41,TileTable[Level],$D41,TileTable[Item_Name],$E41)>0,SUMIFS(TileTable[Olsen_Cost],TileTable[Section],$C41,TileTable[Level],$D41,TileTable[Item_Name],$E41),""),"0") -> 0 | P41: =O41*M41 -> 0 | Q41: =(M41/SUM($M$8:$M$30,$M$32:$M$43,$M$45:$M$56,$M$58:$M$69,$M$71:$M$82,$M$84:$M$95,$M$97:$M$108,$M$110:$M$121,$M$123:$M$134))*$V$5 -> 0 | R41: =P41-Q41 -> 0 | S41: =IF(R41>0,R41/$S$6,R41) -> 0
...

Sheet Tile Product Lists
A1: Tile Section List | C1: Tile_Level_Kitchen_Backsplash | D1: Tile_Level_Floor_Tile | E1: Tile_Level_Listel | F1: Tile_Level_Shower_Pan_Tile | G1: Tile_Level_Shower_Tub_Wall_Tile | H1: Tile_Level_Sill | I1: Tile_Level_Knee_Wall_Cap | J1: Tile_Level_Curb | K1: Tile_Level_Carpet | L1: Tile_Level_LVP | M1: Tile_Level_Wood | P1: Tile_Product_Kitchen_Backsplash_Level_1 | Q1: Tile_Product_Kitchen_Backsplash_Level_2 | R1: Tile_Product_Kitchen_Backsplash_Level_3 | S1: Tile_Product_Kitchen_Backsplash_Level_4 | T1: Tile_Product_Kitchen_Backsplash_Level_5 | U1: Tile_Product_Kitchen_Backsplash_Level_6 | V1: Tile_Product_Kitchen_Backsplash_Level_7 | W1: Tile_Product_Kitchen_Backsplash_Level_8 | X1: Tile_Product_Kitchen_Backsplash_Level_9 | Y1: Tile_Product_Floor_Tile_Level_1 | Z1: Tile_Product_Floor_Tile_Level_2 | AA1: Tile_Product_Floor_Tile_Level_3 | AB1: Tile_Product_Floor_Tile_Level_4 | AC1: Tile_Product_Floor_Tile_Level_5 | AD1: Tile_Product_Floor_Tile_Level_6 | AE1: Tile_Product_Floor_Tile_Level_7 | AF1: Tile_Product_Floor_Tile_Level_8 | AG1: Tile_Product_Floor_Tile_Level_9 | AH1: Tile_Product_Listel_Level_1 | AI1: Tile_Product_Listel_Level_2 | AJ1: Tile_Product_Listel_Level_3 | AK1: Tile_Product_Listel_Level_4 | AL1: Tile_Product_Listel_Level_5 | AM1: Tile_Product_Shower_Pan_Tile_Level_1 | AN1: Tile_Product_Shower_Pan_Tile_Level_2 | AO1: Tile_Product_Shower_Pan_Tile_Level_3 | AP1: Tile_Product_Shower_Pan_Tile_Level_4 | AQ1: Tile_Product_Shower_Pan_Tile_Level_5 | AR1: Tile_Product_Shower_Tub_Wall_Tile_Level_1 | AS1: Tile_Product_Shower_Tub_Wall_Tile_Level_2 | AT1: Tile_Product_Shower_Tub_Wall_Tile_Level_3 | AU1: Tile_Product_Shower_Tub_Wall_Tile_Level_4 | AV1: Tile_Product_Shower_Tub_Wall_Tile_Level_5 | AW1: Tile_Product_Shower_Tub_Wall_Tile_Level_6 | AX1: Tile_Product_Shower_Tub_Wall_Tile_Level_7 | AY1: Tile_Product_Shower_Tub_Wall_Tile_Level_8 | AZ1: Tile_Product_Shower_Tub_Wall_Tile_Level_9 | BA1: Tile_Product_Sill_Level_1 | BB1: Tile_Product_Knee_Wall_Cap_Level_1 | BC1: Tile_Product_Curb_Level_1 | BD1: Tile_Product_Carpet_Level_1 | BE1: Tile_Product_LVP_Level_1 | BF1: Tile_Product_Wood_Level_1
A2: Kitchen Backsplash | C2: Level 1 | D2: Level 1 | E2: Level 1 | F2: Level 1 | G2: Level 1 | H2: Level 1 | I2: Level 1 | J2: Level 1 | K2: Level 1 | L2: Level 1 | M2: Level 1 | P2: Ceramic Subway BG 3" x 6" - Running Bond (1/2 offset) | Q2: Ceramic Subway 4" x 16" - 1/3 offest or stack bond- w/ 3x10 BN | R2: Ceramic Subway BG Beveled 4" x 10" - 1/3 offset or stack bond - w/ 3x10 BN | S2: Broadway 3" x 12" - Running Bond (1/2 offset) or Stack Bond w/Jolly | T2: Beveled Brick 2" x 4" Mosaic Horizontal straight w/ Jolly | U2: Aran 5/8" glass/stone stack mosaic - 12" x12" sheet | V2: 3D Hex Recycled Glass - Mosaic - 12" x 12" Sheet Straight w/Jolly | W2: Marble Slide - Diana Royal Polished -11" x 17" - Straight w/Jolly | X2: Arabesque BV/Ice/Wht polished marble 12" x 14" Mosaic Straight w/Jolly | Y2: Boston 18" x 18" - Straight (no offset) | Z2: Cambridge 12" x 24" - Stack Bond or 1/3 Offset | AA2: Emilia 12" x 24" - Stack Bond or 1/3 Offset | AB2: Alliance- 12" x 24" - Stack Bond or 1/3 Offset | AC2: Annora 12" x 24" - Stack Bond or 1/3 Offset | AD2: Absolute Slate 12" x 24" - Stack Bond or 1/3 Offset | AE2: Casblanca Hex 8" x 9" - Straight (no offset) | AF2: Masterstone Polished or Matte- 32"x32" Straight (no offset) | AG2: Carenza 24" X 48" Stack Bond or 1/3 Offset | AH2: Comet Stratos - White Marble/ Glass Blend - 4" x 12" listel - (1/3 sheet) | AI2: Aran - 5/8" glass/stone stack mosaic - 4" x 12" listel - (1/3 sheet) | AJ2: Glossy Glass 2" x 4" Offset Mosaic 4" x 12" - (1/3 Sheet) | AK2: Gemstone Mosaic 4" x 12" Listel | AL2: LH Stairs 2"x10" Stacked or Offset 4"x10" | AM2: Boston 2" x 2"- Straight | AN2: Cambridge 2" x 2" - Stack Bond or 1/3 Offset | AO2: Alliance - 2" x 2" Mosaic 12" x 12" sheet - straight | AP2: Absolute Slate - 2" x 2" Mosaic - Straight | AQ2: 3D Hex Recycled Glass Mosaic 11" x 13" sheet | AR2: Boston 12" x 12" - Straight (no offset) | AS2: Cambridge 12" x 24" - Stack Bond or 1/3 Offset | AT2: Ceramic Bright 3" x 6" - Running Bond | AU2: Alliance- 12" x 24" - Stack Bond or 1/3 Offset | AV2: Annora 12" x 24" - Stack Bond or 1/3 Offset | AW2: Absolute Slate 12" x 24" - Stack Bond or 1/3 Offset | AX2: Arctic White Polished- 24" x 24" - Straight (no offset) | AY2: Masterstone Polished or Matte- 32"x32" Straight (no offset) | AZ2: Carenza 24" X 48" Stack Bond or 1/3 Offset | BA2: Elustra White | BB2: Elustra White | BC2: Elustra White | BD2: Carpet Product 1 | BE2: LVP Product 1 | BF2: Campbell Creek
A3: Floor Tile | C3: Level 2 | D3: Level 2 | E3: Level 2 | F3: Level 2 | G3: Level 2 | Q3: Ceramic Subway BG Beveled 3" x 6" - Running Bond (1/2 offset) - w/2x6 BN | R3: Maiolica 3" x 6" - Stack Bond or Running Bond w/ 3x6 BN | S3: Casablanca 8" x 8" - Straight w/Jolly | T3: Diamond Herringbone BG Mosaic 12" x 12" sheet - w/Jolly | U3: Autumn Mist - Random - Linear Glass Blend Mosaic - 12" x 12" Sheet | V3: Arrow Gold - Mosaic - 11.75" x 12" Sheet Straight w/Jolly | W3: Marble Slide - Veonra polished 11" x 17" Straight w/Jolly | X3: Arabesque Bianco Venato Dol. pol marble 12" x 14" Mosaic Straight w/Jolly | Y3: Ferrara 18" X 18" - Straight (no offset) | Z3: Carrara 12" x 24" Stack Bond or 1/3 Offset | AA3: Madreas Nogal 6" x 24" - 1/3 Offset | AB3: Bartons Creek 8" x 33" - Stack Bond or 1/3 Offset | AC3: Carenza Matte - 24" x 24" - Straight (no offset) | AD3: Apini Hex- 9"x10.5" Straight (no offset) | AE3: Cottage 9" x 40" - Stack Bond or 1/3 Offset | AF3: Stauaro Polish or Matte- 32"x32" Straight (no offset) | AG3: Era 24" X 48" Stack Bond or 1/3 Offset | AH3: Crackle Glass Slate - 1" x 2" Brick Mosaic - 3x12 listel - (1/4 sheet) | AI3: Autumn Mist Random Linear Glass Mosaic - 4x12" listel - (1/3 sheet) | AJ3: Midpark Random Rainstorm 2" Mosaic - 4" x 12" listel (1/3 Sheet) | AK3: Lighthouse 2"x10" stacked or offset 4"x10" | AM3: Ferrara 2" X 2" - Straight | AN3: Carrara 2" x 2" Stack Bond or 1/3 Offset | AO3: Beach 2" x 2" Mosaic 12" x 12" sheet - straight | AP3: Carenza -Statuary unpolished - 2" x 2" Mosaic - Straight | AQ3: Aran 5/8" glass/stone stack mosaic - 12" x12" sheet | AR3: Ferrara 12" X 12" Straight (no offset) | AS3: Carrara 12" x 24" Stack Bond or 1/3 Offset | AT3: Ceramic Bright 6" x 6" - Straight (no offset) | AU3: Beach 11" x 22" - Stack Bond or 1/3 Offset | AV3: Aura Dolce Wave 6" x 18" - Stack Bond or 1/3 Offset | AW3: Acrtic White 12" x 24" - Stack Bond or 1/3 offset | AX3: Broadway 3" x 12" - Running Bond (1/2 offset) or Stack Bond | AY3: Stauaro Polish or Matte- 32"x32" Straight (no offset) | AZ3: Era 24" X 48" Stack Bond or 1/3 Offset | BA3: Elustra Bisque | BB3: Elustra Bisque | BC3: Elustra Bisque | BF3: Essence
A4: Listel | C4: Level 3 | D4: Level 3 | E4: Level 3 | F4: Level 3 | G4: Level 3 | S4: Eden 3" x 11" - Stack Bond or Running Bond w/ Jolly | T4: Herringbone BG Mosaic -Antique White 12" x 12" sheet - w/Jolly | U4: Comet White Stone/Glass Blend Mosaic - 12" x 12" Sheet | V4: Baltia Mini-brick white - Mosaic - 12" x 12" Sheet Straight w/Jolly | W4: Midpark Random 2" Mosaic - Rainstorm - 12" x 12" sheet Straight w/Jolly | X4: Chevron polished marble 13" x 12" Mosaic Straight w/Jolly | Y4: Travertino 18" x 18" - Straight (no offset) | Z4: Skyline 18" x 18" - Straight | AA4: Palma 12" x 24" - Stack Bond or 1/3 Offset | AB4: Beach 22" x 22" - Straight (no offset) | AC4: Carenza Matte- 12 x 24" - Stack Bond or 1/3 Offset | AD4: Arctic White Matte- 24" x 24" - Straight (no offset) | AE4: Marble Folio 24" x 24" Straight (no offset) | AG4: Pro Matte 24" X 48" Stack Bond or 1/3 Offset | AH4: Crackle Glass White Pearl - 1" x 2" Brick Mosaic 3x12 listel - (1/4 sheet) | AI4: Baltia Mini-brick white Mosaic 4x12 Listel - (1/3 sheet) | AJ4: Raine Random Linear Mosaic 6" x 11" listel - (1/2 sheet) | AK4: Shaved pebble 12" x 12" sheet- stock colors | AM4: Travertino 2" x 2" - Straight | AN4: Skyline 2" x 2" - Straight | AO4: Brescia 2" x 2" Mosaic 12" x 12" sheet - straight | AP4: Charisma Naturale 2" x 2" Mosaic 12" x 12" sheet - straight | AQ4: GEMSTONE MOSAIC - 11.25" x 11.87" | AR4: Travertino 12" x 12" - Straight (no offset) | AS4: Skyline 10" x 13" - Stack Bond | AT4: Emilia 12" x 24" - Stack Bond or 1/3 Offset | AU4: Brescia 11" x 22" - Stack Bond (no offset) | AV4: Carenza Matte- 12 x 24" - Stack Bond or 1/3 Offset | AW4: Carenza 12 x 24" - Stack Bond or 1/3 Offset | AX4: Casblanca Hex 8" x 9" - Straight (no offset) | AZ4: Pro Matte 24" X 48" Stack Bond or 1/3 Offset | BA4: Eng. Botticino | BB4: Eng. Botticino | BC4: Eng. Botticino | BF4: Frontier
A5: Shower Pan Tile | C5: Level 4 | D5: Level 4 | E5: Level 4 | F5: Level 4 | G5: Level 4 | S5: Flow Hexagon 8" x 9" - Horizontal Straight w/Jolly | T5: Hexagon MG Mosaic - 12" x 12" sheet - w/Jolly | U5: Crackle Glass Slate - 1" x 2" Brick Mosaic - 12" x 12" sheet | V5: Geohex recycled glass - Mosaic - 11" x 13" Sheet Straight w/Jolly | W5: Safari Stacked- Elephant 12" x 12" Horizontal - Straight w/Jolly | X5: Fish Scale BVD polished marble 12" x 12" (.80) Mosaic Straight w/Jolly | Z5: Vancouver 18" x 18" - Straight | AA5: Skyline 12" x 24" - Stack Bond or 1/3 Offset | AB5: Brescia 22" x 22" - Straight (no offset) | AC5: Harden Valley 8" x 48" - 1/3 Offset or Random | AD5: Arctic White Polished- 24" x 24" - Straight (no offset) | AE5: Masterstone Polished or Matte- 16"x32" Stack Bond or 1/3 offset | AG5: Pro Polished 24" X 48" Stack Bond or 1/3 Offset | AH5: Crackle Glass Wood Vein - 1" x 2" Brick Mosaic 3x12 listel- (1/4 sheet) | AI5: Icicle Stratos - Calcutta & Glass Mosaic - 4x12" listel - (1/3 sheet) | AJ5: Safari Elephant Stacked 4" x 12" (1/3 sheet) | AM5: Vitra Matte 2" X 2" - Straight | AN5: Vancouver 2" x 2" - Straight | AO5: Cavatina - 2" x 2" Brick Mosaic - Straight | AP5: Hexacycle Carrara 11" x 13" sheet | AQ5: Geohex Recycled Glass Mosaic 11" x 13" sheet | AS5: Vancouver 10" x 38" - Stack Bond | AT5: Palma 12" x 24" - Stack Bond or 1/3 Offset | AU5: Ceramic Bright 4" x 16" - Running Bond | AV5: Ceramic Bright Bevel 4" x 10" - Running Bond | AW5: Carenza Matte - 24" x 24" - Straight (no offset) | AX5: Eden 3" x 11" - Stack or 1/3 Offset | AZ5: Pro Polished 24" X 48" Stack Bond or 1/3 Offset | BA5: Eng. Carrara | BB5: Eng. Carrara | BC5: Eng. Carrara
A6: Shower / Tub Wall Tile | C6: Level 5 | D6: Level 5 | E6: Level 5 | F6: Level 5 | G6: Level 5 | S6: Flow I - 3" x 12" - Stack Bond or Running Bond w/ Jolly | T6: Lantern BG Mosaic 12" x 12" sheet - w/ Jolly | U6: Crackle Glass White Pearl - 1" x 2" Brick Mosaic - 12" x 12" sheet | V6: Glossy Glass - 2" x 4" - Offset - Mosaic - 12" x 12" Sheet Straight w/Jolly | W6: Skyline - Staggered Mosaic Polished - 12" x 12" sheet - Straight w/Jolly | X6: Fish Scale Dol/Ice/Van polished marble 12" x 12" (.80) Mosaic Straight w/Jolly | AA6: Vancouver 12"x24" - Stack Bond or 1/3 Offset | AB6: Dublin- 13"x13" Straight (no offset) | AC6: Lariks- 8"x48" 1/3 Offset or Random | AD6: Carenza Polished- 12 x 24" - Stack Bond or 1/3 Offset | AE6: Nolita - 18" x 36" - Stack Bond (no offset) | AH6: Crystal Stone Pearl Linear Mosaic - 4" x 12" Listel (1/3 sheet) | AI6: Meteor Random Mosaic 4" x 12" Listel - (1/3 Sheet) | AJ6: Silver Star White Random Blend Linear Mosaic - 6" x 12" (1/2 sheet) | AO6: Empire 2" x 2" Mosaic 12" x 12" sheet - straight | AP6: Hexacycle Crema 11" x 13" sheet | AQ6: Linker White Wood Mosaic 10.8" x 10.8" sheet | AS6: Villa 10" x 13" - Stack Bond | AT6: Skyline 12" x 24" - Stack Bond or 1/3 Offset | AU6: Ceramic Bright Beveled 3" x 6" - Running Bond | AV6: Ceramic Bright Wavy 10" x 28" - Stack Bond or 1/3 Offset | AW6: Casablanca 8" x 8" - Straight (no offset) | AX6: Flow 3" x 12" Special Colors - Stack Bond or 1/3 Offset
A7: Sill | C7: Level 6 | D7: Level 6 | G7: Level 6 | S7: Flow II - 3" x 12" - Stack Bond or Running Bond w/ Jolly | T7: Penny Round BG Black Mosaic 12" x 12" sheet - w/ Jolly 5/16" | U7: Crackle Glass Wood Vein - 1" x 2" Brick Mosaic - 12" x 12" sheet | V7: Lamplight recycled glass - Mosaic - 13" x 13" Sheet Straight w/Jolly | W7: Time Grey glass/stone Mosaic 12 x 12 Straight w/Jolly | X7: Linker Mosaic - 10.8" x 10.8" sheet Straight w/Jolly | AB7: Empire 12" x 24" - Stack Bond or 1/3 Offset | AC7: Linen 12" x 24" - Stack Bond or 1/3 Offset | AD7: Carenza Polished- 24" x 24" - Straight (no offset) | AE7: Rever- 8"x48" 1/3 Offset or Random | AH7: Glass Blend Brick Mosaic 1" x 3" - Alpine - 3" x 12" Listel (1/4 sheet) | AI7: Stone/Glass Mosaic 5/8" x 5/8" - 3" X 12" Listel - Carrera (1/4 sheet) | AJ7: Skyline - Staggered Mosaic Polished - 4" x 12" listel - (1/3 sheet) | AO7: Gotham 2" x 2" Mosaic 12" x 12" sheet - straight | AP7: Hexacycle Grey 11" x 13" sheet | AQ7: Shaved pebble 12" x 12" sheet- stock colors | AT7: Vancouver 12"x24" - Stack Bond or 1/3 Offset | AU7: Crayon 4" x 12" - Running Bond | AV7: Linen 12" x 24" - Stack Bond or 1/3 Offset | AW7: Contro Iconica- 12"x24" Stack Bond or 1/3 offset | AX7: Flow Hex 8" x 9" - Straight (no offset)
A8: Knee Wall Cap | C8: Level 7 | D8: Level 7 | G8: Level 7 | S8: Flow Picket 3" x 12" - Horizontal Straight w/Jolly | T8: Penny Round BG Grey Mosaic 12" x 12" sheet -w/ Jolly 5/16" | U8: Crystal Stone Linear Mosaic Pearl - 12" x 12" - Straight | V8: Pinwheel Quartzite 12" x 12" Horizontal - Straight w/Jolly | W8: Verona Staggered Pol 5/8" x 1 1/4" Mosaic - 12" x 12" sht Straight w/Jolly | AB8: Gotham - 12" x 24" - Stack Bond or 1/3 Offset | AC8: Marmo Matte- 12"x24" Stack Bond or 1/3 offset | AD8: Casablanca 8" x 8" - Straight (no offset) | AE8: Stauaro Polish or Matte- 16"x32" Stack Bond or 1/3 offset | AH8: Kolda - 1" x 1" Stone Mosaic 3" x 12" listel - (1/4 sheet) | AI8: Time Grey Glass/Stone Mosaic 3x12 (1/4 Sheet) | AJ8: Squarecycle Grey 2x2 Mosaic - 4" x 12" listel - (1/3 sheet) | AO8: Hexagon 2" x 2" Matte Glaze Black - 12" Mosaic | AP8: Historia - 2" x 2" Mosaic 12" x 12" sheet - straight | AQ8: Verona Staggered Polished 5/8" x 1 1/4" Mosaic - 12" x 12" sheet | AU8: Dublin- 13"x13" Straight (no offset) | AV8: Marmo Matte- 12"x24" Stack Bond or 1/3 offset | AW8: Contro Iconica- 24"x24" Straight (no offset) | AX8: Flow Picket 3" x 12" - Straight (no offset)
A9: Curb | C9: Level 8 | D9: Level 8 | G9: Level 8 | S9: Maiolica Crackled 3" x 12" -Stack Bond or Running Bond w/ Jolly | T9: Penny Round BG White Mosaic 12" x 12" sheet - w/ Jolly 5/16" | U9: Elongate Hex Carrara Mosaic 12" x 13"sheet w/Jolly straight | V9: Shaved Pebbles - 12" x 12" Mosaic - Straight w/Jolly | AB9: Ibiza 12" x24" - Stack Bond or 1/3 Offset | AC9: Marmo Matte- 24"x24" Straight (no offset) | AD9: Contro Iconica- 12"x24" Stack Bond or 1/3 offset | AE9: Terra - 8" x 8" Square - straight | AH9: Pinwheel Mosaic Quartzite - 12x12 Brick Mosaic 3x12 listel - (1/4 sheet) | AJ9: Verona Staggered Polished 5/8" x 1 1/4" Mosaic - 4 x 12" (1/3 sheet) | AO9: Hexagon 2" x 2" Matte Glaze Tender Gray - 12" Mosaic | AP9: Legend II - 2" x 2" Mosaic 12" x 12" sheet - straight | AU9: Empire 12" x 24" - Stack Bond or 1/3 Offset | AV9: Masterstone Matte- 12"x24" Stack Bond or 1/3 | AW9: Flow 3" x 12" Standard Colors - Stack Bond or 1/3 Offset | AX9: Maiolica Crackled 3" x 12" - Stack Bond or 1/3 Offset
