Workbook

Sheet Customer Option Cover Page 
D2: Any changes that are requested after color selections and/or construction has begun will be subject to a $250.00 charge at the discretion of the builder. No mchanges will be performed until signed by both parties and payment is made in full to Olsen Custom Homes. This is a non-refundable option agreement. However should items not get installed a full refund of individual option(s) will be given at closing.
C3: CUSTOMER OPTION FORM #1
B5: DATE: | C5: =TODAY() -> 46240
B6: CUSTOMER: | C6: Olsen Veranda Bay Model #2 | F6: Allowance Estimated Pricing Subject to change, based on final installed price
B7: JOB ADDRESS: | C7: 183 Stillwater Drive, Flagler Beach
B8: ALLOWANCES
B9: PRICE REQUEST ITEMS BY HOMEOWNER | D9: Please Note: Pricing may fluctuate on items that are priced out for the Homeowners from the time of price request to time of homeowner approval. A charge or credit will apply at the time of ordering.
B10: CLARIFICATIONS (NO PRICE CHANGE)
B11: PRICING READY TO SHOW HOMEOWNER
B12: HOMEOWNER REVIEWING
B13: PRICING APPROVED BY HOMEOWNER
B14: TOP PRIORITY
B15: Category | C15: Countertop Allowance Thickness: 1cm Edge Style: Mitered | D15: Date | E15: Revised by: | F15: Allowance | G15: Final price | H15: Difference | I15: In House Notes
C16: Design Meeting Times
I17: cross ref all bt
C18: Allowances
B19: Allowance | C19: Appliance Allowance | D19: 46134 | E19: ST | F19: 4000 | G19: Overage To be paid directly to the Appliance Co. | H19: Need final list from johns
B20: Allowance - Cabinets | C20: Cabinetry Allowance: This is allowance for base cabinetry throughout the home. Added items or options will be priced separately below. Hardware included in priicng | D20: 4/22/2026 5/11/2026 5/12/2026 | E20: ST ST ST | F20: 30200 | G20: 32038 | H20: =G20-F20 -> 1838 | I20: added
B21: Option | C21: Kitchen: Add 18" Stacks. Solid Doors. | D21: 05.11.2026 5/12/2026 | E21: ML ST | G21: Olsen Costs $3,376 | H21: 3376 | I21: added
B22: Option | C22: Pantry: add Cabinets in pantry-cabinets only | G22: Olsen Cost $4,584.00 | H22: 4584 | I22: Added
B23: Option | C23: Laundry: Add dog crate location | G23: Olsen Cost $1,145.00 | H23: 1145 | I23: added
B24: Option | C24: Laundry cabinets (not sink side) | G24: Olsen Cost$1,777.00 | H24: 1777 | I24: added
B25: Allowance | C25: Countertop Allowance: Cambria Windsor Brass: NOTE: This color was selected because it is being given by Cambria for the model. Manufacturer: Skyline Material: Quartz Color: Windsor Brass Level: 12 Finish: Polished Locations: Kitchen Island Top Thickness: 3cm Edge Style: Eased Kitchen Island Double Waterfall Edge Thickness: 3cm Edge Style: Eased Kitchen Hood Wrapped 3 sides Thickness: 1cm Edge Style: Mitered | D25: 4/19/2026 5/15/2026 | E25: ML ST | F25: 14335 | G25: =F25+H25 -> 29757.15 | H25: 15422.15 | I25: Homeowner cost with standard mark up - ST | J25: added
C26: Super White: Manufacturer: Skyline Material: Quartz Color: Super White Level: 3 Finish: Polished Locations Kitchen Perimeter Edge Style: Eased No Backsplash Master Bathroom Countertops No Backsplash No Side Splash Bath #2 Edge Style: Eased 4" Backsplash & Sidesplash Bath #3 Edge Style: Eased 4" Backsplash & Sidesplash
C27: White Fantasy: Manufacturer: Skyline Material: Marble Color: White Fantasy Level: 4 Finish: Polished Locations: Laundry Edge Style: Eased 4" Backsplash and Sidesplash Dog Crate Edge Style: Eased 4" Backsplash and Sidesplash (Left side)
B28: Allowance | C28: Drywall/Duro/Densglass Material Allowance: | H28: NEED INVOICE
C29: Ceiling Texture: Regular Knockdown Drywall Texture: Knockdown All Corner Beads: Style - Squared (all locations) Window Corner Bead: Squared throughout | D29: 4/2/2026 4/14/2026 | E29: TJ ST | H29: Per Platinum Features
B30: Allowance | C30: Electrical Allowance: This allowance is for base electrical for the home. Upgraded or added items will be priced separately below. | D30: 4/14/2026 5/14/2026 | E30: ST ST ST | F30: 26500 | G30: 29685 | H30: =G30-F30 -> 3185 | I30: added-need to change estimate file #'s
C31: Redlined Additions: Exterior - Add switch and soffit lights Exterior - Add switch and (2) column lights Laundry - Add (2) recess cans Laundry - Add 20 amp circuit for audio Laundry - Add (1) recess can in hallway Pantry - Add (4) recess cans Garage Closet - Add switch and (1) recess can Drop Off Area - Add switch for 2 - 4" recess cans Wet Bar - Add switch for 3 - 4" recess cans Bed #3 & 4 - Add swtiched outlet Hallway - Add (2) 6" recess cans and (1) 4" recess can Nook - Add switch and (4) recess cans Summer Kitchen - Add (4) recess cans. Lanai - Add (4) recess cans Family Room - Add (4) recess cans Entertainment Center - Add swithc for (2) 4" cans Kitchen Island - Add switch and (2) pendant light locations. Ktichen - Add switch and (6) 24" over cabinet lights Kitchen - Add (5) task LED power strips Study - Add switch and (4) recess cans | D31: 46126 | E31: ST | G31: Break out price is $8,245 | H31: Included in allowance above
C32: Master - Add (3) recess cans: (2) in closets and (1) in Master Hallway Master Toilet - Add (1) recess can Add switch for Chandeleir - braced for heavy fixture Master Bath - Add switch and (4) recess cans. Master Vanity - Add (1) recess can and (2) wall light locations Credit for 40 amp wall over Credit for (5) LED under cab lights
B33: Allowance | C33: Exterior Door Allowance: Front Door: Description: Full Lite Atrium Impact Glass Door Glass: Rain Glass Finish-Exterior: Painted - See Paint Schedule Finish-Interior: Painted - Match Interior Doors/Trim - See Paint Selection Sheet Height: Per Plans See Plans Active Door and Swing Direction | D33: 4/2/2026 5/15/2026 | E33: TJ ST | F33: 11200 | G33: 8700 | H33: =G33-F33 -> -2500 | I33: added
C34: Rear Lanai Doors: Description: Full Lite Atrium Impact Glass Door Finish-Exterior: Painted - See Paint Schedule Finish-Interior: Painted - Match Interior Doors/Trim - See Paint Selection Sheet Height: Per Plans Locations: Master Bedroom Hallway
C35: Garage to Interior: Door Style: Rockport Description: Molded - 5 Panel Smooth Bead & Cove Finish/Color: See Paint Selection Sheet Size: Per Plans Quantity: Per Plans
C36: Garage To Exterior Side: Door Style: Carrara Molded - 2 Panel Squaretop Smooth Bead & Cove Finish/Color: See Paint Selection Sheet Size: Per Plans Quantity: Per Plans Location: Per Plans
B37: Allowance | C37: Exterior Finish Allowance: Stucco Material: Exterior Finish - Linear Skip Trowel (Most popular) Banded Windows: Per plan Decorative Foam Bands: Per plan Exterior Ceilings: Per Plan Interior Garage Walls: Smooth Skim Coat Stucco & Painted Accent Corbel: Material: Wood Finish: Stain MW 415 Tidal Wood Stained: See Paint Schedule Areas: Per Plan Qty: 22 (Per Plans) Rustic Wood Bracket w/ Offset Brace, Thorton Style, Craftsman Ends, Size: 4"W x 14"D x 26"H Type: Rough Sawn Western Red Cedar Corbel Detail F: Style: Per Plan Size: Per Plan Material: Foam Finish: Stucco (to be paint grade) See Paint Schedule | D37: 46131 | E37: ML | F37: 33000 | G37: 29617 | H37: =G37-F37 -> -3383 | I37: added
B38: Allowance | C38: Per Platinum Features Garage Door 1 & 2: Manufacturer: Clopay Finish: Painted - See Paint Selection Sheet Height: Per Plans Width: Per Plans | D38: 4/2/2026 4/14/2026 | E38: TJ ST | F38: 5594 | G38: 5594 | H38: 0 | I38: added
C39: Garage Door Opener: Lift Master 2220L Chain Drive ¾ HP with Camera
B40: Allowance | C40: Gas/Propane: 250 Gallon Buried Tank (Leased) Included locations for Gas piping (200') - Cooktop Pool Heater Tankless Hot Water Heater | D40: 46114 | E40: TJ | G40: Olsen Cost | H40: 6110
B41: Allowance | C41: Impact Fees Allowance: | D41: 46134 | E41: ST | G41: Olsen Cost | H41: 9423.87 | I41: added
B42: Allowance | C42: Landscaping Allowance: | D42: 46134 | E42: ST | F42: 23500 | G42: Overage To be paid directly to the Landscaping Co. | H42: need bobbys docs
...

Sheet Allowances
A1: ='DNU Customer Option Cover Page'!C6 -> Olsen Veranda Bay Model #2
A2: ='DNU Customer Option Cover Page'!C7 -> 183 Stillwater Drive, Flagler Beach
B3: DATE: | C3: =TODAY() -> 46240
B4: CUSTOMER: | C4: ='DNU Customer Option Cover Page'!C6 -> Olsen Veranda Bay Model #2
B5: JOB ADDRESS: | C5: ='DNU Customer Option Cover Page'!C7 -> 183 Stillwater Drive, Flagler Beach
B7: Category | C7: Description | D7: Date | E7: Allowance | F7: Actuals | G7: Difference
B8: Allowance | C8: Drywall/Duro/Densglass Material Allowance:
B9: Allowance | C9: Electrical Allowance: This allowance is for base electrical for the home. Upgraded or added items will be priced separately below.
B10: Allowance | C10: Impact Fees Allowance:
B11: Allowance | C11: Lumber Allowance:
B12: Allowance | C12: Plumbing Allowance: This allowance is for base plumbing for the home. Upgraded or added items will be priced separately below.
B13: Allowance | C13: Roofing Allowance:
B14: Allowance | C14: Sitework Allowance: THERE MAY BE ADDITONAL WORK ON TH LOT AT THE END OF THE PROJECT AS WELL AS POTENTIAL DEGRASS OF AREAS WE LEAVE UNITL THE END.
B15: Allowance | C15: Truss Allowance
B16: Allowance | C16: Windows Allowance:

Sheet Options
A1: ='DNU Customer Option Cover Page'!C6 -> Olsen Veranda Bay Model #2
A2: ='DNU Customer Option Cover Page'!C7 -> 183 Stillwater Drive, Flagler Beach
B3: DATE: | C3: =TODAY() -> 46240
B4: CUSTOMER: | C4: =A1 -> Olsen Veranda Bay Model #2
B5: JOB ADDRESS: | C5: =A2 -> 183 Stillwater Drive, Flagler Beach
B7: Category | C7: Description | D7: Date | E7: Revised by: | F7: Contract Pricing Page | G7: Final price | H7: Difference

Sheet DNU  Customer Option Cover Page
D2: Any changes that are requested after color selections and/or construction has begun will be subject to a $250.00 charge at the discretion of the builder. No mchanges will be performed until signed by both parties and payment is made in full to Olsen Custom Homes. This is a non-refundable option agreement. However should items not get installed a full refund of individual option(s) will be given at closing.
C3: CUSTOMER OPTION FORM #1
B5: DATE: | C5: =TODAY() -> 46240
B6: CUSTOMER: | C6: Olsen Veranda Bay Model #2 | F6: Allowance Estimated Pricing Subject to change, based on final installed price
B7: JOB ADDRESS: | C7: 183 Stillwater Drive, Flagler Beach
B8: ALLOWANCES
B9: PRICE REQUEST ITEMS BY HOMEOWNER | D9: Please Note: Pricing may fluctuate on items that are priced out for the Homeowners from the time of price request to time of homeowner approval. A charge or credit will apply at the time of ordering.
B10: CLARIFICATIONS (NO PRICE CHANGE)
B11: PRICING READY TO SHOW HOMEOWNER
B12: HOMEOWNER REVIEWING
B13: PRICING APPROVED BY HOMEOWNER
B14: TOP PRIORITY
B15: Category | C15: Description | D15: Date | E15: Revised by: | F15: Allowance | G15: Final price | H15: Difference | I15: Buildertrend
B16: Allowance | C16: Appliance Allowance | D16: 46134 | E16: ST | F16: 4000 | G16: Overage To be paid directly to the Appliance Co. | H16: Need final list from johns | I16: Need final list from johns
B17: Allowance | C17: Cabinetry Allowance: This is allowance for base cabinetry throughout the home. Added items or options will be priced separately below. | D17: 46134 | E17: ST | F17: 36175 | G17: 35377 | H17: =G17-F17 -> -798 | I17: Need to add colors
B18: Revisons | C18: Kitchen Stove Wall:
C19: Kitchen Ref. Wall:
C20: Kitchen Island:
B21: Option | C21: Add Kitchen Hood with blower | D21: 46134 | E21: ST | H21: 2655.38
B22: Option | C22: Add Kitchen Dog Food & Water Station | D22: 46134 | E22: ST | H22: 480
B23: Option | C23: Add uppers in the laundry room | D23: 46134 | E23: ST | H23: 4492.31
B24: Option | C24: Add Entertainment shelving with cabinet company | D24: 46134 | E24: ST | H24: 1820
B25: Option | C25: Add Stop and Drop Cabinet | D25: 46134 | E25: ST | H25: 6223.08
B26: Option | C26: Master Bedroom W.I.C.s | D26: 05.07.2026 | E26: ML | H26: NEED PRICING
B27: Allowance | C27: Drywall/Duro/Densglass Material Allowance: | H27: NEED INVOICE
C28: Ceiling Texture: Regular Knockdown Drywall Texture: Knockdown All Corner Beads: Style - Squared (all locations) Window Corner Bead: Squared throughout | D28: 4/2/2026 4/14/2026 | E28: TJ ST | H28: Per Platinum Features | I28: Green on BT
B29: Allowance | C29: Electrical Allowance: This allowance is for base electrical for the home. Upgraded or added items will be priced separately below. | D29: 46126 | E29: ST | F29: 26500 | H29: Per Platinum Features
C30: Redlined Additions: Exterior - Add switch and soffit lights Exterior - Add switch and (2) column lights Laundry - Add (2) recess cans Laundry - Add 20 amp circuit for audio Laundry - Add (1) recess can in hallway Pantry - Add (4) recess cans Garage Closet - Add switch and (1) recess can Drop Off Area - Add switch for 2 - 4" recess cans Wet Bar - Add switch for 3 - 4" recess cans Bed #3 & 4 - Add swtiched outlet Hallway - Add (2) 6" recess cans and (1) 4" recess can Nook - Add switch and (4) recess cans Summer Kitchen - Add (4) recess cans. Lanai - Add (4) recess cans Family Room - Add (4) recess cans Entertainment Center - Add swithc for (2) 4" cans Kitchen Island - Add switch and (2) pendant light locations. Ktichen - Add switch and (6) 24" over cabinet lights Kitchen - Add (5) task LED power strips Study - Add switch and (4) recess cans | D30: 46126 | G30: Olsen Cost | H30: 8245
C31: Master - Add (3) recess cans: (2) in closets and (1) in Master Hallway Master Toilet - Add (1) recess can Add switch for Chandeleir - braced for heavy fixture Master Bath - Add switch and (4) recess cans. Master Vanity - Add (1) recess can and (2) wall light locations Credit for 40 amp wall over Credit for (5) LED under cab lights
B32: Field Changes - Electrical | C32: Following area were shifted due to beam installation: Living Room CAN LEDs Kitchen CAN LEDs Nook CAN LEDs | D32: 04.19.2026 | E32: ML | H32: Req. Pricing from John GPS 4/22 - ST | I32: tommy need to add beams and new location to new set of plans
B33: Allowance | C33: Exterior Door Allowance: Front Door: Description: Full Lite Atrium Impact Glass Door Glass: Rain Glass Finish-Exterior: Painted - See Paint Schedule Finish-Interior: Painted - Match Interior Doors/Trim - See Paint Selection Sheet Height: Per Plans See Plans Active Door and Swing Direction | D33: 4/2/2026 4/14/2026 | E33: TJ ST | F33: 11000 | G33: 7593.42 | H33: Per Platinum Features
C34: Rear Lanai Doors: Description: Full Lite Atrium Impact Glass Door Finish-Exterior: Painted - See Paint Schedule Finish-Interior: Painted - Match Interior Doors/Trim - See Paint Selection Sheet Height: Per Plans Locations: Master Bedroom Hallway
C35: Garage to Interior: Door Style: Rockport Description: Molded - 5 Panel Smooth Bead & Cove Finish/Color: See Paint Selection Sheet Size: Per Plans Quantity: Per Plans
C36: Garage To Exterior Side: Door Style: Carrara Molded - 2 Panel Squaretop Smooth Bead & Cove Finish/Color: See Paint Selection Sheet Size: Per Plans Quantity: Per Plans Location: Per Plans | I36: Rockport cant be used outside
B37: NO ALLOWANCE?????????????? | C37: Exterior Finish Allowance: IS THERE AN EXTERIOR FINSIH ALLOWANCE? Stucco Material: Exterior Finish - Linear Skip Trowel (Most popular) Banded Windows: Per plan Decorative Foam Bands: Per plan Exterior Ceilings: Per Plan Interior Garage Walls: Smooth Skim Coat Stucco & Painted Accent Corbel: Material: Wood Finish: Stain MW 415 Tidal Wood Stained: See Paint Schedule Areas: Per Plan Qty: 22 (Per Plans) Rustic Wood Bracket w/ Offset Brace, Thorton Style, Craftsman Ends, Size: 4"W x 14"D x 26"H Type: Rough Sawn Western Red Cedar Corbel Detail F: Style: Per Plan Size: Per Plan Material: Foam Finish: Stucco (to be paint grade) See Paint Schedule | D37: 46131 | E37: ML | F37: 33000 | G37: Stucco - $25K Bahama Shutters $5,800 | H37: need pricing | I37: overage would be due to accent corbel
B38: Allowance? | C38: Entertainment Center:
B39: Allowance | C39: Per Platinum Features Garage Door 1 & 2: Manufacturer: Clopay Finish: Painted - See Paint Selection Sheet Height: Per Plans Width: Per Plans | D39: 4/2/2026 4/14/2026 | E39: TJ ST | F39: 5594 | G39: 5594 | H39: 0
C40: Garage Door Opener: Garage Door Opener - Lift Master 8160W 1/2 HP Chain Drive Includes 2 Units & 1 push button for each unit Above model is discontinued Lift Master 2220L Chain Drive ¾ HP with Camera
B41: Allowance | C41: Countertop Allowance: | D41: 46131 | E41: ML | H41: need to send to skyline for pricing
C42: Windsor Brass: NOTE: This color was selected because it is being given by Cambria for the model. Manufacturer: Skyline Material: Quartz Color: Windsor Brass Level: 12 Finish: Polished Locations: Kitchen Island Top Thickness: 3cm Edge Style: Eased Kitchen Island Double Waterfall Edge Thickness: 3cm Edge Style: Eased Kitchen Hood Wrapped 3 sides Thickness: 1cm Edge Style: Mitered | D42: 46131 | E42: ML | H42: need to send the cambrisa for ordering
...

Sheet Pavers
A1: ='DNU Customer Option Cover Page'!C6 -> Olsen Veranda Bay Model #2
A2: ='DNU Customer Option Cover Page'!C7 -> 183 Stillwater Drive, Flagler Beach
A4: Budget
A6: 1400 SF
A8: Driveway Pavers | B8: 9100
A10: Total | B10: =SUM(B5:B9) -> 9100
A12: Paver Allowance: More may be needed once survey is finalized and approved. Vendor: ITS Manufacturer: Tremron Color: Glacier (Pervious) Installation Pattern: Euro 3pc Random (See Attached Photo) Locations: Driveway Walkway Front Entry
A14: ITS - OPTION #1
A15: Tremron Pervious Opt $8.58 sf
A16: 2021 SF | B16: =2021*8.58 -> 17340.18
A18: Total | B18: =SUM(B16:B17) -> 17340.18
A19: Budget | B19: 9100 | D19: NO CLUE WHAT ALL THIS MEANS
A20: Over | B20: =B18-B19 -> 8240.18
A22: Allowance | B22: 1400 | C22: SF
A23: Selected | B23: 2100 | C23: SF
A24: Over | B24: =B23-B22 -> 700 | C24: SF
A25: Charge HO $10 per sf over | B25: =700*10 -> 7000
A27: Upgraded paver Permeable | B27: =8.58-6.5 -> 2.08 | C27: SF
A29: 2100 | B29: sf
A30: Charge HO | B30: =2100*B27 -> 4368
A32: Profit | B32: =B30+B25-B20 -> 3127.82
A35: ITS - OPTION #2
A36: Tremron Standard $6.50 sf
A37: 2021 SF | B37: =6.5*2021 -> 13136.5
A39: Total | B39: =SUM(B37:B38) -> 13136.5
A40: Budget | B40: 9100
A41: Over | B41: =B39-B40 -> 4036.5
A43: Allowance | B43: 1400 | C43: SF
A44: Selected | B44: 2100 | C44: SF
A45: Over | B45: =B44-B43 -> 700 | C45: SF
A46: Charge HO $10 per sf over | B46: =700*10 -> 7000
A48: Profit | B48: =B46-B41 -> 2963.5
A51: ITS - OPTION #3
A52: Tremron Permeable Opt $9.14 sf
A53: 2021 SF | B53: =2021*9.14 -> 18471.94
A55: Total | B55: =SUM(B53:B54) -> 18471.94
A56: Budget | B56: 9100
A57: Over | B57: =B55-B56 -> 9371.94
A59: Allowance | B59: 1400 | C59: SF
A60: Selected | B60: 2100 | C60: SF
...

Sheet Summer Kitchen
A1: ='DNU Customer Option Cover Page'!C6 -> Olsen Veranda Bay Model #2
A2: ='DNU Customer Option Cover Page'!C7 -> 183 Stillwater Drive, Flagler Beach
A5: Option #1 | D5: Level 2 Granite $42 per sf | H5: Level 5 Granite $66 per sf
A6: DKA | D6: Modern Me | H6: Modern Me
A7: 11' Captiva Cab C-COK11 | B7: 4050
A8: 6' Captiva Cab C-COK6 | B8: 2376 | D8: White star board doors | E8: 8411 | H8: White star board doors | I8: 8411
A9: Tax & Freight | B9: =450+450 -> 900 | D9: Upgraded level 1 doors | E9: 852.5 | H9: Upgraded level 1 doors | I9: 852.5
A10: Total | B10: =SUM(B7:B9) -> 7326 | D10: Solid smooth color | E10: 1350 | H10: Solid smooth color | I10: 1350
D12: Total | E12: =SUM(E7:E11) -> 10613.5 | H12: Total | I12: =SUM(I7:I11) -> 10613.5
A13: WPG
A14: Level 2: Fantasy Brown | B14: 3757.5 | D14: WPG | H14: Skyline
A15: Grill cutout | B15: 150 | D15: Level 2: Natural Stone Fantasy Brown | E15: 2125.2 | H15: 46 SFLevel 5 @ $66 per SF | I15: =46*66 -> 3036
A16: Sink | B16: 230 | D16: 26.6 SF With 24" Backsplash | E16: 1228.7 | H16: 26.6 SF With 24" Backsplash | I16: =26.6*66 -> 1755.6
A17: Total | D17: Sink | E17: 176 | H17: Sink | I17: 230
D18: Total | E18: =SUM(E15:E17) -> 3529.9 | H18: Total | I18: =SUM(I15:I17) -> 5021.6
A19: Johns ABC
A20: Grill C3-C2C34 | B20: 2096 | D20: Johns ABC | H20: Johns ABC
A21: C3-SSD | B21: 878 | D21: Grill C3-C2C34 | E21: 2096 | H21: Grill C3-C2C34 | I21: 2096
A22: C3-DPC31 | B22: 1440
A23: C3-STC | B23: 580
A24: C3-DA2426 | B24: 300
A25: 7% Tax | B25: =SUM(B20:B24)*0.07 -> 370.58
A26: Total | B26: =SUM(B21:B25) -> 3568.58 | D26: 7% Tax | E26: =SUM(E21:E25)*0.07 -> 146.72 | H26: 7% Tax | I26: =SUM(I21:I25)*0.07 -> 146.72
D27: Total | E27: =SUM(E21:E26) -> 2242.72 | H27: Total | I27: =SUM(I21:I26) -> 2242.72
A28: Faucet 7882SRS | B28: =400.88*1.07 -> 428.9416
D29: Faucet 7882SRS | E29: 442 | H29: Faucet 7882SRS | I29: 442.43
A30: Olsen Total Cost | B30: =B28+B26+B17+B10 -> 11323.522
D31: Olsen Total Cost | E31: =SUM(E12+E18+E27+E29) -> 16828.12 | F31: Math did not capture everything. ST 7/27 | H31: Olsen Total Cost | I31: =SUM(I12+I18+I27+I29) -> 18320.25
D32: Level 2 Granite Retail | E32: =SUM(E31/0.65) -> 25889.415 | H32: Level 5 Granite Retail | I32: =SUM(I31/0.65) -> 28185

Sheet Stone
A1: ='DNU Customer Option Cover Page'!C6 -> Olsen Veranda Bay Model #2
A2: ='DNU Customer Option Cover Page'!C7 -> 183 Stillwater Drive, Flagler Beach
A4: Stone: Manufacturer: Pioneer Stone Product Code: STV-ASH-002 Product Details Color Austin Collection Ashlar Flats Height: 3 1/2 – 9 1/2 Length: 5 1/4 – 16 Thickness: 1 1/4 – 2 1/2 Weight: 7.98 lbs/ln ft Corners Height: 3 1/2 – 9 1/2 Length: 5 1/4 – 13 3/4 Thickness: 1 1/4 – 2 1/2 Return: 4 Weight: 9.14 lbs/ln ft Areas: See plans Front Elevation Rear Column Bases to 3' High Summer Kitchen Base Summer Kitchen Island Grout Color: White (IF NEEDED) (Dry-stack Install Method, Or Tight install)
A6: Take Off - Front Elevation
A7: Left Side | B7: 64 | C7: SF
A8: Left Side corners | B8: 12 | C8: LF
A9: Front Entry | B9: 175 | C9: SF
A10: Front Entry corners | B10: 124 | C10: LF
A11: Right Side | B11: 46 | C11: SF
A12: Right Side corners | B12: 8 | C12: LF
A14: Take Off - Rear Columns to 4' High
A15: Rear Columns | B15: 80 | C15: SF
A16: Rear Columns corner | B16: 54 | C16: LF
A18: Total Stone SF | B18: =B7+B9+B11+B15 -> 365 | C18: SF
A19: Total Stone Corners | B19: =B8+B10+B12+B16 -> 198 | C19: LF
D21: Real Cost to Olsen | F21: $11.50 per sf
A22: J&N Stone 390 SF @ $19.50/sf | B22: =19.5*390 -> 7605 | D22: =11.5*390 -> 4485
A23: Includes Material & Install
A25: Charge for add / .65 | B25: =B22/0.65 -> 11700
A27: Stone: Interior Arches: Manufacturer: Pioneer Stone Product Code: STV-ASH-002 Product Details Color Austin Collection Ashlar Areas: See plans Front Elevation Rear Column Bases Grout Color: White (IF NEEDED) (Dry-stack Install Method, Or Tight install) Wet Bar Stone Elipse (Front wide only) Nook Header Stone Elipse (all 3 sides)
A28: Take Off - Wet Bar
A29: Wet Bar Eclipse | B29: 40 | C29: SF
A31: Take Off - Nook Header
A32: Nook Eclipse | B32: 54 | C32: SF
A34: Total Stone SF | B34: =B29+B32 -> 94 | C34: SF
D36: Real Cost to Olsen | F36: $13.50 per sf
A37: J&N Stone 100 SF @ $19.50/sf | B37: =100*19.5 -> 1950 | D37: =13.5*100 -> 1350
A38: Includes Material & Install
A40: Charge for add / .65 | B40: =B37/0.65 -> 3000
A42: Master Bathroom Shower Tub Wall (around the windows): Manufacturer: Pioneer Stone Product Code: STV-ASH-002 Product Details Color Austin Collection Ashlar Areas: See plans Front Elevation Rear Column Bases Grout Color: White (IF NEEDED) (Dry-stack Install Method, Or Tight install)
A44: Master Shower Tub Wall
A45: Wall | B45: 50 | C45: SF
A47: Total Stone SF | B47: =B42+B45 -> 50 | C47: SF
D49: Real Cost to Olsen | F49: $13.50 per sf
A50: J&N Stone 100 SF @ $19.50/sf | B50: =50*19.5 -> 975 | D50: =13.5*50 -> 675
A51: Includes Material & Install
A53: Charge for add / .65 | B53: =B50/0.65 -> 1500

Sheet Fireplace
A1: ='DNU Customer Option Cover Page'!C6 -> Olsen Veranda Bay Model #2
A2: ='DNU Customer Option Cover Page'!C7 -> 183 Stillwater Drive, Flagler Beach
A4: Great Room Fireplace Unit: The Sideline 72" Manufacturer: Touchstone Model: 80015 Description: The Sideline 72 Inch Recessed Smart Electric Fireplace 80015 - Smart-home ready with lifelike LED flames, front heat vent, and a sleek recessed design. Includes logs and crystals for a customizable, connected fireplace experience. Remote: Touchstone Fireplace Remote Driftwood & Clear Crystals Notes: See Framing
A5: Fireplace Mantle: Brand: The Barn Collection Interior or Exterior Placement Interior Height & Depth 10"H x 10"D Length 78" (6.5 ft) Finishing Color Weathered Siding Mounting Installation Mantel Notching QTY: 1
A6: Center Face Material: (Stone) Manufacturer: Pioneer Stone Product Code: STV-ASH-002 Product Details Color Austin Collection Ashlar Living Room Fireplace Center Wall Edge to Edge Floor to Ceiling.
A8: Touchstone Fireplace | B8: 749.25
A9: 80015
B10: 300
A11: Barnwood Collection Mantle
A12: Mantle 10" x 10" x 8' | B12: =1158.75*1.07 -> 1239.8625
A14: Mantle Install | B14: 250
D15: Real Cost to Olsen
A16: J&N Stone 92 SF @ $19.50/sf | B16: 1796.39 | D16: =12.5*92 -> 1150
A17: Includes Material & Install
A19: Olsen Total Cost | B19: =B8+B12+B14+B16+B10 -> 4335.5025
A20: Charge HO / .65 | B20: =B19/0.65 -> 6670.0038
A22: Fireplace Unit: Master: The Forte Elite 40" Manufacturer: Touchstone Model: 80052 Description: The Forte Elite 40 Inch Recessed Smart Electric Fireplace 80052 Remote: Touchstone Fireplace Remote Driftwood & Clear Crystals Notes: See Framing
A23: Center Face Material: (Stone) Manufacturer: Pioneer Stone Product Code: STV-ASH-002 Product Details Color Austin Collection Ashlar Master Fireplace Wall to Wall Floor to Ceiling.
A24: Fireplace Mantle: Mantle - Master Brand: The Barn Collection Interior or Exterior Placement Interior Height & Depth 10"H x 10"D Length 48" (4 ft) Finishing Color Weathered Siding Mounting Installation Mantel Notching QTY: 1
A26: Touchstone Fireplace | B26: 799.074
A27: 80052
B28: 300
A29: Barnwood Collection Mantle
A30: Mantle 10" x 10" x 4' | B30: =877.5*1.07 -> 938.925
A32: Mantle Install | B32: 250
D33: Real Cost to Olsen
A34: J&N Stone 58 SF @ $19.50/sf | B34: =19.5*58 -> 1131 | D34: =12.5*58 -> 725
A35: Includes Material & Install
A37: Olsen Total Cost | B37: =B26+B30+B32+B34+B28 -> 3418.999
A38: Charge HO / .65 | B38: =B37/0.65 -> 5259.9985

Sheet Plumbing
A1: ='DNU Customer Option Cover Page'!C6 -> Olsen Veranda Bay Model #2
A2: ='DNU Customer Option Cover Page'!C7 -> 183 Stillwater Drive, Flagler Beach
A4: Plumbing: Kitchen Pot Filler: Added During Color Selection. This price is for the add location, material and labor. Pot Filler: Manufacturer: Moen Model: S665BL Style: Modern Matte Black Pot Filler Kitchen Faucet Finish: Matte Black Qty: 1 Location: Kitchen
B5: Builder Cost
A6: Added plumb Line | B6: 150
A7: Fixture: S665BL | B7: =894.45*1.07 -> 957.0615 | C7: https://www.fergusonhome.com/moen-s665/s688947?uid=3595192
A8: Total Cost | B8: =SUM(B6:B7) -> 1107.0615
A9: Charge HO / .65 | B9: =B8/0.65 -> 1703.1715
A12: Garbage Disposal: Upgraded from a Platinum Featured Collection to the below: Manufacturer: Moen Model: EXL100C Description: EX Series 1 Horsepower Lighted Garbage Disposal
B13: Wholesale $
A14: Badger 1/2 HP Dispoasl | B14: =154.23*1.07 -> 165.0261
A16: Moen EXL100C | B16: =265.68*1.07 -> 284.2776
A18: Olsen Cost | B18: =B16-B14 -> 119.2515
A19: Charge HO / .65 | B19: 0 | C19: EO included
A22: Upgraded: This is a Platinum Featured Collection. The Finish is an upgrade. Master Bath Faucet: Manufacturer: Moen Model: TV64433BZG Collection: Jase Description: Jase Bronzed gold two-handle high arc bathroom faucet Finish: Bronzed Gold Qty: 2 Location: Master Bath
A23: Platinum Serires | B23: Wholesale $
A24: TV6620ORB (2) | B24: =300*1.07*2 -> 642
A26: TV64433BZG (2) | B26: =386.76*2*1.07 -> 827.6664
A28: Olsen Cost | B28: =B26-B24 -> 185.6664
A29: Charge HO / .65 | B29: =B28/0.65 -> 285.64062
A32: Upgraded from a Platinum Featured Collection to the below: Linear Drain Location: Master Bath Tile-In Linear Shower Drain Model: Per Plumber QTY: 2 Finish: To Match Shower Head Finish Supplied By: Plumber
A34: (2) Included | B34: =2*25 -> 50
A36: (2) 36" Installed | B36: =2*348 -> 696
A38: Olsen Cost | B38: =B36-B34 -> 646
A39: Charge HO / .65 | B39: =B38/0.65 -> 993.84615
A42: Upgraded: This is a Platinum Featured Collection. The Finish is an upgrade. Master Fixture - Manufacturer: Moen Model: T430BZG Collection: Jase Description: Jase Bronzed gold two-handle non diverter roman tub faucet Finish: Bronzed Gold Quantity: 1 Location: Master Bathroom
A43: Platinum Serires | B43: Wholesale $
A44: T933ORB | B44: =493.89*1.07 -> 528.4623
A46: T430BZG | B46: =512.38*1.07 -> 548.2466
A48: Olsen Cost | B48: =B46-B44 -> 19.7843
A49: Charge HO / .65 | B49: =B48/0.65 -> 30.437385

Sheet HVAC
A1: ='DNU Customer Option Cover Page'!C6 -> Olsen Veranda Bay Model #2
A2: ='DNU Customer Option Cover Page'!C7 -> 183 Stillwater Drive, Flagler Beach
A4: Upgrading from Carrier to Bosch Model: Bosch IDS Heat Pump Premium Connected Series Condensing Unit 2 & 4 Ton Capacity | R454B
A6: Olsen Cost
A7: 2 Ton | B7: 1100
A8: 4 Ton | B8: 1300
A9: Total | B9: =SUM(B7:B8) -> 2400
A10: Charge HO/.65 | B10: =B9/0.65 -> 3692.3077
A12: Add (2) 4" Pleated filters
A14: Olsen Cost
A15: (2) 4" pleated filters | B15: =500*2 -> 1000
A16: Total | B16: =SUM(B15:B15) -> 1000
A17: Charge HO/.65 | B17: =B16/0.65 -> 1538.4615
A19: Add (2) UV Lights
A21: Olsen Cost
A22: (2)UV Lights | B22: =350*2 -> 700
A23: Total | B23: =SUM(B22:B22) -> 700
A24: Charge HO/.65 | B24: =B23/0.65 -> 1076.9231

Sheet Laundry dog crate location cost
A1: Modern Me
C2: Charge / .65
A3: Modern Me Cabinets | B3: 1145 | C3: =SUM(B3/0.65) -> 1761.5385
A4: Countertops for dog crate location and over washer and dryer. | B4: 1734.66 | C4: =SUM(B4/0.65) -> 2668.7077
A5: 6" waterfall and mitered edge
A6: Doors for dog crate | B6: 259.84 | C6: =SUM(B6/0.65) -> 399.75385
C8: =SUM(C3:C6) -> 4830
A10: Verns
C11: Charge / .65
A12: Modern Me Cabinets | B12: 975 | C12: =SUM(B12/0.65) -> 1500
A13: Countertops for dog crate location and over washer and dryer. | B13: 1734.66 | C13: =SUM(B13/0.65) -> 2668.7077
A14: 6" waterfall and mitered edge
A15: Doors for dog crate | B15: 259.84 | C15: =SUM(B15/0.65) -> 399.75385
C17: =SUM(C12:C15) -> 4568.4615
A19: Winter Park Granite - White Fantasy $57 SF
A20: Laundry Dog Crate w. 4" BS 24.68 SF | B20: =24.68*62.7 -> 1547.436
A21: 6" waterfall 1.1 SF | B21: =1.1*62.7 -> 68.97
A22: Laundry dog crate mitered edge - 4.3 LF @ $27.50 LF | B22: =4.3*27.5 -> 118.25
B23: =SUM(B20:B22) -> 1734.656 | C23: ST 7/24/2026

Sheet Cabinets modern me
I1: Eric's pricing to play with
A2: 46154 | B2: MODERN ME PRICING | J2: MODERN ME PRICING
A3: Model Name: Veranda Bay 2 | B3: Masterpiece | D3: Selected Finishes= | I3: Model Name: 2 | J3: Masterpiece | L3: Selected Finishes=
A4: 183 Stillwater Olsen Model CABINETS | I4: 183 Stillwater Olsen Model CABINETS
A5: Plywood Boxes in stain finish throughout / 1 roll- out included in kitchen base cabinets | I5: Plywood Boxes in stain finish throughout / 1 roll- out included in kitchen base cabinets
A6: Standard Layouts | B6: Std Doors | C6: hardware | D6: Paint upgrade | E6: Translucent upgrade | I6: Standard Layouts | J6: Std Doors | K6: hardware | L6: Paint upgrade | M6: Paint w/highlight and stain w/glaze upgrade | N6: Translucent upgrade | O6: Custom Match paint | P6: Ages stain weathered stain aged paint
A7: Kitchen Perimeter Deluxe | B7: 14436 | I7: Kitchen Perimeter Deluxe | J7: 14436 | L7: 2165 | M7: 2743 | N7: 3609 | O7: 3609 | P7: 4331
A8: Kitchen Island | B8: 3035 | E8: 759 | I8: Kitchen Island | J8: 3035 | L8: 455 | M8: 577 | N8: 759 | O8: 759 | P8: 911
A9: Kitchen Island Veneer | B9: 702 | E9: 176 | I9: Kitchen Island Veneer | J9: 702 | L9: 176
A10: Hood vent blower only | B10: 850 | I10: Hood vent blower only | J10: 850 | L10: 128 | M10: 162 | N10: 213 | O10: 213 | P10: 255
A11: Custom 42" Wide appliance Garage | B11: 751 | I11: Custom 42" Wide appliance Garage | J11: 751 | L11: 113 | M11: 143 | N11: 188 | O11: 188 | P11: 225
A12: Kitchen hardware | C12: =SUM(96+162) -> 258 | I12: Kitchen hardware | K12: =SUM(96+162) -> 258 | L12: 0 | M12: 339
A13: Master Bath | B13: 4763 | I13: Master Bath | J13: 4763 | L13: 714 | M13: 905 | N13: 1191 | O13: 1191 | P13: 1429
A14: Master bath hardware | C14: 80 | I14: Master bath hardware | K14: 80 | L14: 0
A15: Bath #2 | B15: 1785 | E15: 446 | I15: Bath #2 | J15: 1785 | L15: 268 | M15: 339 | N15: 446 | O15: 446 | P15: 536
A16: Bath #2 hardware | C16: standard | I16: Bath #2 hardware | K16: standard | L16: 0
A17: Bath #3 | B17: 1017 | E17: 254 | I17: Bath #3 | J17: 1017 | L17: 153 | M17: 193 | N17: 254 | O17: 254 | P17: 305
A18: Bath #3 hardware | C18: standard | I18: Bath #3 hardware | K18: standard | L18: 0
A19: Stop & Drop | B19: 983 | I19: Stop & Drop | J19: 983 | L19: 147 | M19: 187 | N19: 246 | O19: 246 | P19: 295
A20: Laundry sink side | B20: 1516 | D20: 227 | I20: Laundry sink side | J20: 1516 | L20: 227 | M20: 288 | N20: 379 | O20: 379 | P20: 455
A21: Laundry sink hardware | C21: standard | I21: Laundry sink hardware | K21: standard
A22: Totals | B22: =SUM(B7:B20) -> 29838 | C22: =SUM(C7:C21) -> 338 | D22: =SUM(D7:D20) -> 227 | E22: =SUM(E7:E20) -> 1635 | I22: Totals | J22: =SUM(J7:J20) -> 29838
A23: Total w/ all Finishes Olsen cost | B23: =SUM(B22:E22) -> 32038 | I23: Total w/ all Finishes Olsen cost
A24: Upcharge 65% | B24: =SUM(B23/0.65) -> 49289.231
A26: Options | F26: Total | G26: upgrade 65% | I26: Options
A27: 18" Top Row cabinets | B27: 3376 | F27: =SUM(B27:E27) -> 3376 | G27: =SUM(F27/0.65) -> 5193.8462 | I27: 18" Top Row cabinets | J27: 3376 | L27: 506 | M27: 641 | N27: 844 | O27: 844 | P27: 1013
A28: Wet Bar | B28: 2034 | E28: 509 | F28: =SUM(B28:E28) -> 2543 | G28: =SUM(F28/0.65) -> 3912.3077 | I28: Wet Bar | J28: 2034 | L28: 305 | M28: 386 | N28: 509 | O28: 509 | P28: 310
A29: Wet Bar Shelvs wrapping structure | B29: 2561 | E29: 640 | F29: =SUM(B29:E29) -> 3201 | G29: =SUM(F29/0.65) -> 4924.6154 | I29: Wet Bar Shelvs wrapping structure | J29: 2561 | L29: 384 | M29: 487 | N29: 640 | O29: 640 | P29: 768
A30: Fireplace wall | B30: 2004 | F30: =SUM(B30:E31) -> 2020 | G30: =SUM(F30/0.65) -> 3107.6923 | I30: Fireplace wall | J30: 2004 | L30: 301 | M30: 381 | N30: 501 | O30: 501 | P30: 601
A31: Entertainment fireplace wall hardware | C31: 16 | I31: Entertainment fireplace wall hardware | K31: 16
A32: Pantry | B32: 3986 | D32: 598 | F32: =SUM(B32:E33) -> 4584 | G32: =SUM(F32/0.65) -> 7052.3077 | I32: Pantry | J32: 3986 | L32: 598 | M32: 757 | N32: 997 | O32: 997 | P32: 1196
A33: Pantry hardware | C33: standard | I33: Pantry hardware | K33: standard
A34: Laundry Pantry only | B34: 1538 | D34: 231 | F34: =SUM(B34:E35) -> 1777 | G34: =SUM(F34/0.65) -> 2733.8462 | I34: Laundry Pantry only | J34: 1538 | L34: 231 | M34: 292 | N34: 385 | O34: 385 | P34: 461
A35: Laundry pantry hardware | C35: 8 | I35: Laundry pantry hardware | K35: 8
A36: Laundry Dog Crate only | B36: 996 | D36: 149 | F36: =SUM(B36:E36) -> 1145 | G36: =SUM(F36/0.65) -> 1761.5385 | I36: Laundry Dog Crate only | J36: 996 | L36: 149 | M36: 189 | N36: 249 | O36: 249 | P36: 299
A37: Option Total | B37: =SUM(B27:B36) -> 16495 | C37: =SUM(C27:C36) -> 24 | D37: =SUM(D27:D36) -> 978 | E37: =SUM(E27:E36) -> 1149 | I37: Option Total | J37: =SUM(J27:J36) -> 16495
A38: Option Total w/ Finishes Olsen Cost | B38: =SUM(B37:E37) -> 18646 | F38: TOTAL UPGRDES | G38: =SUM(G27:G36) -> 28686.154 | I38: Option Total w/ Finishes Olsen Cost
A40: Total cost for Masterpiece Cabinets installed with all above-includes options-Olsen Cost | D40: =SUM(B38+B23) -> 50684
A41: Credit From Masterpeice and ModernMe | D41: 32092
B42: Total due | D42: =SUM(D40-D41) -> 18592
...

Sheet Cabinets VERNS
A2: 46227 | B2: VERNS PRICING
A3: Model Name: Veranda Bay 2 | B3: Entra
A4: 183 Stillwater Olsen Model CABINETS
A6: Standard Layouts | B6: Std Doors | C6: hardware
A7: Kitchen Perimeter Deluxe | B7: =16242-B27 -> 12942
A8: Kitchen Island | C8: =12*7 -> 84
A9: Kitchen Island Veneer
A10: Hood vent blower only
A11: Custom 42" Wide appliance Garage
A12: Kitchen hardware | C12: =364-C27-C8 -> 196
A13: Master Bath | B13: 4523
A14: Master bath hardware | C14: 140
A15: Bath #2 | B15: 1402
A16: Bath #2 hardware | C16: 42
A17: Bath #3 | B17: 887
A18: Bath #3 hardware | C18: 28
A19: Stop & Drop | B19: 300
A20: Laundry sink side | B20: 1525 | D20: 4174 | E20: =D20-B20 -> 2649
A21: Laundry sink hardware | C21: =8*7 -> 56 | D21: 70
A22: Totals | B22: =SUM(B7:B20) -> 21579 | C22: =SUM(C7:C21) -> 546
A23: Total Olsen Cost | B23: =SUM(B22:C22) -> 22125
A24: Upcharge 65% | B24: =SUM(B23/0.65) -> 34038.462
A26: Options | D26: Total | E26: upgrade 65%
A27: 18" Top Row cabinets | B27: 3300 | C27: =12*7 -> 84 | D27: =SUM(B27:C27) -> 3384 | E27: =SUM(D27/0.65) -> 5206.1538
A28: Wet Bar | B28: 2190 | D28: =B28+C29 -> 2246 | E28: =SUM(D28/0.65) -> 3455.3846
A29: Wet Bar Hardware | C29: 56
A30: Entertainment wall | B30: 1622 | D30: =SUM(B30:C31) -> 1650 | E30: =SUM(D30/0.65) -> 2538.4615
A31: Entertainment wall Hardware | C31: 28
A32: Pantry | B32: 3605 | D32: =SUM(B32:C33) -> 3675 | E32: =SUM(D32/0.65) -> 5653.8462
A33: Pantry hardware | C33: 70
A34: Laundry Pantry only | B34: =E20-B36 -> 1674
A35: Laundry pantry hardware | C35: 14
A36: Laundry Dog Crate only | B36: 975 | D36: =SUM(B36:C36) -> 975 | E36: =SUM(D36/0.65) -> 1500
A37: Option Total | B37: =SUM(B27:B36) -> 13366 | C37: =SUM(C27:C36) -> 252
A38: Option Total w/ Finishes Olsen Cost | B38: =SUM(B37:C37) -> 13618 | D38: TOTAL UPGRDES | E38: =SUM(E27:E36) -> 18353.846
A40: Total cost for Masterpiece Cabinets installed with all above-includes options-Olsen Cost
A41: Credit From Masterpeice and ModernMe
B42: Total due
A44: Master Closet
A45: Her Closet Wall Hang w/ dresser unit | B45: 1874
...

Sheet Stop & Drop
A1: ='DNU Customer Option Cover Page'!C6 -> Olsen Veranda Bay Model #2
A2: ='DNU Customer Option Cover Page'!C7 -> 183 Stillwater Drive, Flagler Beach
A4: Stop and Drop Cabinet: Desk style Cabinet with countertop. See Countertop Allowance Granite: White Fantasy Manufacturer: Skyline Material: Marble Level: 4 Finish: Polished Edge Style: Eased 4" Backsplash and Sidesplash
A6: Modern Me | D6: Verns
A8: Stop & Drop | B8: 983 | D8: Stop & Drop | E8: 300
A10: Total | B10: =SUM(B7:B9) -> 983 | D10: Total | E10: =SUM(E7:E9) -> 300
A12: WPG | D12: WPG
A13: Level 4: White Fantasy | B13: 1003.2 | D13: Level 4: White Fantasy | E13: 1003.2
A14: Marble w/ 4" BS | D14: Marble w/ 4" BS
A17: Olsen Total Cost | B17: =B10+B13 -> 1986.2 | D17: Olsen Total Cost | E17: =E10+E13 -> 1303.2
A18: Included in Base | D18: Included in Base

Sheet Pantry
A1: ='DNU Customer Option Cover Page'!C6 -> Olsen Veranda Bay Model #2
A2: ='DNU Customer Option Cover Page'!C7 -> 183 Stillwater Drive, Flagler Beach
A4: Pantry: Cabinets: Manufacturer: Modern Me Granite: White Fantasy Manufacturer: Skyline Material: Marble Color: White Fantasy Level: 4 Finish: Polished Edge Style: Eased 4" Backsplash and Sidesplash
A6: Modern Me
A8: Pantry | B8: 4584
A10: Total | B10: =SUM(B7:B9) -> 4584
A12: WPG
A13: Level 4 White Fantasy | B13: 762.43
A14: Marble with 4" BS
A15: Sink | B15: 176
A17: Pantry Faucet | B17: 449.77
A20: Olsen Total Cost | B20: =B10+B13+B15+B17 -> 5972.2
A21: Charge HO / .65 | B21: =B20/0.65 -> 9188
A23: Pantry: Cabinets: Manufacturer: Verns Granite: White Fantasy Manufacturer: Skyline Material: Marble Color: White Fantasy Level: 4 Finish: Polished Edge Style: Eased 4" Backsplash and Sidesplash
A25: Verns
A27: Pantry | B27: 3605
A28: Hardware | B28: 70
A29: Total | B29: =SUM(B26:B28) -> 3675
A31: WPG
A32: Level 4 White Fantasy | B32: 762.43
A33: Marble with 4" BS
A34: Sink | B34: 176
A36: Pantry Faucet | B36: 449.77
A39: Olsen Total Cost | B39: =B29+B32+B34+B36 -> 5063.2
A40: Charge HO / .65 | B40: =B39/0.65 -> 7789.5385

Sheet WetBar
A1: ='DNU Customer Option Cover Page'!C6 -> Olsen Veranda Bay Model #2
A2: ='DNU Customer Option Cover Page'!C7 -> 183 Stillwater Drive, Flagler Beach
A4: Modern Me | D4: Verns
A5: Wetbar | B5: 2543 | D5: Wet Bar | E5: =2190+56 -> 2246
A6: Total | B6: =SUM(B5:B5) -> 2543 | D6: Total | E6: =SUM(E5:E5) -> 2246
A8: Winter Park Grantie | D8: Winter Park Grantie
A9: Wet Bar No Backsplash - 27.2 SF | B9: =27.2*70.4 -> 1914.88 | D9: Wet Bar No Backsplash - 27.2 SF | E9: =27.2*70.4 -> 1914.88
A10: Wet Bar 1618 HMR Sink | B10: 176 | D10: Wet Bar 1618 HMR Sink | E10: 176
A11: Total | B11: =SUM(B9:B10) -> 2090.88 | D11: Total | E11: =SUM(E9:E10) -> 2090.88
A13: Faucet 7882SRS | B13: 428.97 | D13: Faucet 7882SRS | E13: =400.88*1.07 -> 428.9416
A15: Olsen Total Cost | B15: =B6+B11+B13+B14 -> 5062.85 | D15: Olsen Total Cost | E15: =E6+E11+E13 -> 4765.8216
A16: Charge HO/.65 | B16: =B15/0.65 -> 7789 | D16: Charge HO/.65 | E16: =E15/0.65 -> 7332.0332
A18: Option: Add Wet Bar Custom Shelves: Custom Design to Install. Brand: The Barn Collection Length: 42" Finish Color: Weathered Siding QTY: 9 Brand: The Barn Collection Length: 72" Finish Color: Weathered Siding QTY: 2
A20: Barnwood Collection
A21: (9) 42" floating shelves | B21: 2063.13
A22: (2) 72" floating Shelves | B22: 805
A23: 7% Tax | B23: =SUM(B21:B22)*0.07 -> 200.7691
A24: Install (10) each @ $100 ea | B24: 900
A25: Total | B25: =SUM(B21:B24) -> 3968.8991
A26: Charge HO/.65 | B26: =B25/0.65 -> 6105.9986
A28: Wet Bar Stone: Add stone in the dry-stack method on the wetbar wall from the countertop to the ceiling using Pioneer Stone, Ashlar Collection in the Austin color. If grout is needed it will be white.
A30: Take Off - Wet Bar Wall
A31: Wetbar countertop to ceiling | B31: 90 | C31: SF
D34: Real Cost to Olsen | F34: $13.50 per sf
A35: J&N Stone 100 SF @ $19.50/sf | B35: =19.5*90 -> 1755 | D35: =13.5*90 -> 1215
A36: Includes Material & Install
A38: Charge for add / .65 | B38: =B35/0.65 -> 2700

Sheet Entertainment
A1: ='DNU Customer Option Cover Page'!C6 -> Olsen Veranda Bay Model #2
A2: ='DNU Customer Option Cover Page'!C7 -> 183 Stillwater Drive, Flagler Beach
A4: Entertainment Cabinets: This is allowance for base cabinets. Added items or options will be priced separately below.
A5: Cabinets: 2 Base Cabinets. See Cabinet Drawing Granite: Super White: Manufacturer: Skyline Material: Quartz Level: 3 Finish: Polished Edge Style: Eased No Backsplash Floating Shelves: Amish Timber Wood Shelves: Shelves - Living room Brand: The Barn Collection Length: 42" Finish Color: Weathered Siding QTY: 4 Install: 2 on each side Spacing: 22"
A7: Modern Me | D7: Verns
A9: Fireplace Wall | B9: 2020 | D9: Entertainment | E9: =1622+28 -> 1650
A11: Winter Park Granite | D11: Winter Park Granite
A12: Level 3 Super White | B12: 528 | D12: Level 3 Super White | E12: 528
A14: Total | D14: Total
A16: Barnwood Collection | D16: Barnwood Collection
A17: Floating Shelves (4) | B17: =917*1.07 -> 981.19 | D17: Floating Shelves (4) | E17: =917*1.07 -> 981.19
A18: Install | B18: 175.81 | D18: Install | E18: =75*4 -> 300
A20: Olsen Total Cost | B20: =B17+B12+B9+B18 -> 3705 | D20: Olsen Total Cost | E20: =E17+E13+E9+E18 -> 2931.19
A21: Charge HO / .65 | B21: =B20/0.65 -> 5700 | D21: Charge HO / .65 | E21: =E20/0.65 -> 4509.5231

Sheet Closets
A1: ='DNU Customer Option Cover Page'!C6 -> Olsen Veranda Bay Model #2
A2: ='DNU Customer Option Cover Page'!C7 -> 183 Stillwater Drive, Flagler Beach
A4: Budget
A6: Master Shelving Per
A7: Plan
A8: 34.5 LF @ $20.57 per LF | B8: =20.57*34.5 -> 709.665
A9: 17.25 LF each WIC
A11: Total | B11: =SUM(B5:B10) -> 709.665
A13: Master Bedroom Custom W.I.C.s: Wall hung closet organizers. In Both His & Her's W.I.C.s
A15: Option #1 | D15: Option #1
A16: Modern Me | D16: Modern Me
A17: Her Closet Wall Mounted | D17: His Closet Wall Mounted
A18: Her Closet Wall Unit | B18: 1874 | D18: His Closet Wall Unit | E18: 1874
A19: Melamine Color upgrde | B19: 173 | D19: Melamine Color upgrde | E19: 173
A20: Total | B20: =SUM(B18:B19) -> 2047 | D20: Total | E20: =SUM(E18:E19) -> 2047
A21: Credit for ventilated | B21: =-(709.67/2) -> -354.835 | D21: Credit for ventilated | E21: =-(709.67/2) -> -354.835
A22: Revised Total | B22: =SUM(B20:B21) -> 1692.165 | D22: Revised Total | E22: =SUM(E20:E21) -> 1692.165
A23: Charge HO / .65 | B23: =B22/0.65 -> 2603.3308 | D23: Charge HO / .65 | E23: =E22/0.65 -> 2603.3308
A25: Option #2 | D25: Option #2
A26: Modern Me | D26: Modern Me
A27: Her Closet Floor Mounted | D27: His Closet Floor Mounted
A28: Her Closet FM Unit | B28: 2507 | D28: His Closet FM Unit | E28: 2507
A29: Melamine Color upgrde | B29: 450 | D29: Melamine Color upgrde | E29: 450
A30: Total | B30: =SUM(B28:B29) -> 2957 | D30: Total | E30: =SUM(E28:E29) -> 2957
A31: Credit for ventilated | B31: =-(709.67/2) -> -354.835 | D31: Credit for ventilated | E31: =-(709.67/2) -> -354.835
A32: Revised Total | B32: =SUM(B30:B31) -> 2602.165 | D32: Revised Total | E32: =SUM(E30:E31) -> 2602.165
A33: Charge HO / .65 | B33: =B32/0.65 -> 4003.3308 | D33: Charge HO / .65 | E33: =E32/0.65 -> 4003.3308

Sheet Tile
A1: ='DNU Customer Option Cover Page'!C6 -> Olsen Veranda Bay Model #2
A2: ='DNU Customer Option Cover Page'!C7 -> 183 Stillwater Drive, Flagler Beach
A4: Budget
A6: Tile Floors matl | B6: 23688
A7: Tile floor labor | B7: Above
A8: Woodfloors | B8: 0
A9: Carpet Install | B9: 0
A10: Master bathroom | B10: 0
A11: Shower flor | B11: 1750
A12: 2nd Floor Duro and Install | B12: 0
A13: Sills | B13: 800
A14: Seat | B14: 0
A15: Tile Walls | B15: 4500
A16: Master Tub | B16: 750
A17: Kitchen Backsplash | B17: 1500
A18: Cermaic fixt | B18: 650
A20: Total | B20: =SUM(B5:B19) -> 33638
A22: MASTER BATH | E22: Unit $ | G22: Total | I22: Olsen $ | K22: Total | M22: Added Cost | O22: Charge HO/.75
A23: CARENZA Oro Polished 12x24
A24: Walls to 8' | B24: 244 | C24: sf | E24: 10.5 | G24: =E24*B24 -> 2562 | I24: 10 | K24: =I24*B24 -> 2440 | M24: =G24-K24 -> 122 | O24: =M24/0.75 -> 162.66667
A25: 8' to 10' | B25: =31*2 -> 62 | C25: sf | E25: 10.5 | G25: =E25*B25 -> 651 | I25: 0 | K25: =I25*B25 -> 0 | M25: =G25-K25 -> 651 | O25: =M25/0.68 -> 957.35294
A26: Shower Bench | B26: 1 | C26: ea | E26: 175 | G26: =E26*B26 -> 175 | I26: 175 | K26: =I26*B26 -> 175 | M26: =G26-K26 -> 0
A27: Niche | B27: 1 | C27: ea | E27: 125 | G27: =E27*B27 -> 125 | I27: 0 | K27: =I27*B27 -> 0 | M27: =G27-K27 -> 125 | O27: =M27/0.68 -> 183.82353
A28: Vanity Wall Arch Behind Mirror | C28: sf | E28: TBD
A29: GOTHAM NERO 2x2 | Q29: =SUM(O36*3) -> 551.47059
A30: Shower Floor | B30: 55 | C30: sf | E30: 17.5 | G30: =E30*B30 -> 962.5 | I30: 19 | K30: =I30*B30 -> 1045 | M30: =G30-K30 -> -82.5
S31: =SUM(Q25+Q34+Q43) -> 0
A32: BATH #2 | S32: =SUM(Q30+Q38+Q46) -> 0
A33: IMMERSE CARRARA 12x24
A34: Walls to 8' | B34: =130-B35 -> 104 | C34: sf | E34: 8 | G34: =E34*B34 -> 832 | I34: 10 | K34: =I34*B34 -> 1040 | M34: =G34-K34 -> -208
A35: 8' to 10' | B35: 26 | C35: sf | E35: 8 | G35: =E35*B35 -> 208 | I35: 0 | K35: =I35*B35 -> 0 | M35: =G35-K35 -> 208 | O35: =M35/0.68 -> 305.88235
A36: Niche | B36: 1 | C36: ea | E36: 125 | G36: =E36*B36 -> 125 | I36: 0 | K36: =I36*B36 -> 0 | M36: =G36-K36 -> 125 | O36: =M36/0.68 -> 183.82353
A37: WAVES LAGUNA 2x2
A38: Shower Floor | B38: 18 | C38: sf | E38: 19 | G38: =E38*B38 -> 342 | I38: 19 | K38: =I38*B38 -> 342 | M38: =G38-K38 -> 0
A40: Bath #3
A41: IMMERSE CARRARA 12x24
A42: Walls to 8' | B42: 112 | C42: sf | E42: 8 | G42: =E42*B42 -> 896 | I42: 10 | K42: =I42*B42 -> 1120 | M42: =G42-K42 -> -224
A43: 8' to 10' | B43: 24 | C43: sf | E43: 8 | G43: =E43*B43 -> 192 | I43: 0 | K43: =I43*B43 -> 0 | M43: =G43-K43 -> 192 | O43: =M43/0.68 -> 282.35294
A44: Niche | B44: 1 | C44: ea | E44: 125 | G44: =E44*B44 -> 125 | I44: 0 | K44: =I44*B44 -> 0 | M44: =G44-K44 -> 125 | O44: =M44/0.68 -> 183.82353
A45: WAVES LAGUNA 2x2
...

Sheet Shelving
A1: ='DNU Customer Option Cover Page'!C6 -> Olsen Veranda Bay Model #2
A2: ='DNU Customer Option Cover Page'!C7 -> 183 Stillwater Drive, Flagler Beach
A4: Upgraded from Drywall Shelving to the following: Shelves - Master Brand: The Barn Collection Length: 24" Finish Color: Weathered Siding QTY: 8 Install: 4 on each side Spacing: 22"
A6: Barnwood Collection
A7: (8) 24" Weathered Shelves | B7: =1147.736*1.07 -> 1228.0775
A9: Install Shelves @ $75 each | B9: =78*8 -> 624
A10: Credit for Drywall Labor | B10: -250
A11: Olsen Total Cost | B11: =SUM(B7:B10) -> 1602.0775
B12: =SUM(B11/0.68) -> 2355.9964

Sheet Beams
A1: ='DNU Customer Option Cover Page'!C6 -> Olsen Veranda Bay Model #2
A2: ='DNU Customer Option Cover Page'!C7 -> 183 Stillwater Drive, Flagler Beach
A4: Beams U-Wrapped Size: 12" W x 10" H Material: Pine Finish: Stain Grade Living Room Tray Qty: 5 Kitchen Qty: 3 Nook Qty: 3 Foyer Tray Qty: 4 (Boarder Style)
D5: Staining | E5: =SUM(B11/C6) -> 10.677507 | F5: LF
A6: All Custom | C6: 184.5 | D6: LF | E6: =B7/C6 -> 58.699187 | F6: per LF | G6: Total Beams | H6: RETAIL | J6: Location | K6: LF | M6: Install/material | N6: Stain
A7: Living Room (5) 16' Long | B7: 10830 | C7: 80 | G7: =SUM(C7*E13) -> 5550.1355 | H7: =SUM(G7/0.65) -> 8538.67 | J7: Living rm | K7: 80 | L7: 58.7 | M7: =SUM(L7*K7) -> 4696 | N7: =SUM(K7*E5) -> 854.20054 | O7: =SUM(M7:N7) -> 5550.2005
A8: Kitchen (3) 16' Long | C8: 48 | G8: =SUM(C8*E13) -> 3330.0813 | H8: =SUM(G8/0.65) -> 5123.202 | J8: Kitchen | K8: 48 | L8: 58.7 | M8: =SUM(L8*K8) -> 2817.6 | N8: =SUM(K8*E5) -> 512.52033 | O8: =SUM(M8:N8) -> 3330.1203
A9: Nook (3) 7.5' Long | C9: 22.5 | G9: =SUM(C9*E13) -> 1560.9756 | H9: =SUM(G9/0.65) -> 2401.5009 | J9: Nook | K9: 22.5 | L9: 58.7 | M9: =SUM(L9*K9) -> 1320.75 | N9: =SUM(K9*E5) -> 240.2439 | O9: =SUM(M9:N9) -> 1560.9939
A10: Foyer Tray (4) 8.5' Long | C10: 34 | G10: =SUM(C10*E13) -> 2358.8076 | H10: =SUM(G10/0.65) -> 3628.9348 | J10: Foyer | K10: 34 | L10: 58.7 | M10: =SUM(L10*K10) -> 1995.8 | N10: =SUM(K10*E5) -> 363.03523 | O10: =SUM(M10:N10) -> 2358.8352
A11: Stain beams | B11: 1970 | J11: TOTALS | K11: =SUM(K7:K10) -> 184.5 | L11: 58.7 | M11: =SUM(M7:M10) -> 10830.15 | N11: =SUM(N7:N10) -> 1970 | O11: =SUM(O7:O10) -> 12800.15
A13: Olsen Total Cost | B13: =SUM(B7:B12) -> 12800 | E13: =SUM(E5:E6) -> 69.376694 | F13: COST PER FOOT
A14: Charge HO / .65 | B14: =B13/0.65 -> 19692.308 | H14: =SUM(H7:H10) -> 19692.308

Sheet Granite
A1: ='DNU Customer Option Cover Page'!C6 -> Olsen Veranda Bay Model #2
A2: ='DNU Customer Option Cover Page'!C7 -> 183 Stillwater Drive, Flagler Beach
A4: Budget
A5: Countertops Kitchen | B5: 7261
A6: Granite laundry | B6: 1037
A7: Granite Master | B7: 3200
A8: Granite bath 2 | B8: 825
A9: Granite bath 3 | B9: 667
A10: Stop & Drop | B10: 1000
A11: Entertainment center top | B11: Option
A12: Wet bar tops | B12: Option
A13: Pantry | B13: Option
A14: All Sinks | B14: 1000
A16: Total | B16: =SUM(B5:B15) -> 14990
A18: Winter Park Granite
A19: Olsen Cost with 10% Discount | B19: 26792.5
A20: Future Client Cost | B20: =B19*1.1 -> 29471.75
A22: 46225
A23: Carmen 2 CM Quartz - 137.2 SF Total @ $70.40 SF
A24: Kitchen Perimeter - 28 SF | B24: =28*70.4 -> 1971.2 | C24: BASE | E24: Charge HO/.65
A25: Kitchen Hood Wrap - 48 SF | C25: =48*70.4 -> 3379.2 | D25: Hood wrap Add | E25: =SUM(C25:C26)/0.65 -> 7037.2923
A26: Mitre Edge 45 degree hood sides - 48 LF @ $24.75 LF | C26: =(48*24.75+7.04) -> 1195.04
E28: Credit for tile backsplash 36 SF | F28: Charge HO/.65
A29: Kitchen stove Area Full Height Backsplash - 26.5 SF | C29: =26.5*70.4 -> 1865.6 | D29: Backsplash upgrade | E29: =-36*19 -> -684 | F29: =SUM(C29+E29)/0.65 -> 1817.8462
A30: (6) Outlet cut outs | B30: No Charge
A31: Wet Bar No Backsplash - 27.2 SF | C31: =27.2*70.4 -> 1914.88 | D31: Wetbar tab
A32: Wet Bar 1618 HMR Sink | C32: 176
A33: Entertainment - 7.5 SF | C33: =7.5*70.4 -> 528 | D33: Entertainment Tab
A34: Super White Quartz 146.3 SF @ $55 SF
A35: Kitchen Island 123" x 63" - 53.81 SF | B35: =53.81*55 -> 2959.55 | C35: BASE
A36: 2 Kitchen Island Waterfalls - 31.5 SF | C36: =31.5*55 -> 1732.5 | D36: Waterfall island Add | E36: =SUM(C36:C37)/0.65 -> 3553.8462
A37: Mitered Edge at Island - 21 LF @ $27.50 lf | C37: =21*27.5 -> 577.5
A38: Polish under | B38: No Charge
A39: Granite Master w. 4" BS - 49 SF | B39: =49*55 -> 2695 | C39: BASE
A40: Granite bath 2 with 4" BS - 14.7 SF | B40: =14.7*55 -> 808.5 | C40: BASE
A41: Granite bath 3 with 4" BS - 11.09 SF | B41: =11.09*55 -> 609.95 | C41: BASE
A42: Bathroom Sinks - 4 @ $60.50 | B42: =60.5*4 -> 242 | C42: BASE
A43: Sink Cutouts | B43: 110 | C43: BASE
A44: 5 Faucet Holes & Bracing | B44: 330 | C44: BASE
A45: White Fantasy Marble - 69.8 SF @ $62.70 SF
...

Sheet Bath Accessories
A1: ='DNU Customer Option Cover Page'!C6 -> Olsen Veranda Bay Model #2
A2: ='DNU Customer Option Cover Page'!C7 -> 183 Stillwater Drive, Flagler Beach
A4: Budget
A6: Ceramic Fixtures | B6: 650
A8: Total | B8: =SUM(B5:B7) -> 650
A10: Upgraded from a Platinum Featured Collection to the below Manufacturer: Moen Model: YB0708BZG Style: Jase Color: Bronzed Gold Description: Jase Bronzed Gold Pivoting Paper Holder QTY: 1 Locations: Master Bathroom Toilet Room — Right side of toilet Manufacturer: Moen Model: YB0786BZG Style: Jase Color: Bronzed Gold Description: Jase Bronzed Gold Towel Ring QTY: 2 Locations: Master Bathroom Sinks Sink 1 (Left side of room): Install on wall to the left of the sink Sink 2 (Right side of room): Install on wall to the right of the sink
A12: Model | B12: Quantity | C12: Total
A13: YB0708BZG | B13: 1 | C13: =37.96*1.07 -> 40.6172
A15: YB0786BZG | B15: 2 | C15: =29.63*2*1.07 -> 63.4082
B17: Total | C17: =SUM(C13:C16) -> 104.0254
B18: Budget | C18: 650
B19: Under Budget | C19: =C18-C17 -> 545.9746

Sheet Cabinets
A1: ='DNU Customer Option Cover Page'!C6 -> Olsen Veranda Bay Model #2
A2: ='DNU Customer Option Cover Page'!C7 -> 183 Stillwater Drive, Flagler Beach
A4: Budget
A6: Cabinets Kitchen | B6: 16900
A7: Cabinets Laundry | B7: 3150
A8: Cabinets master | B8: 7000
A9: Cabinets Bath 2 | B9: 0
A10: Cabinets bath 3 | B10: 1400
A11: Cabinets Bath 4 | B11: 1750
A12: Entertainment center | B12: 2300
A13: Wetbar cabinets | B13: 3675
A14: Total | B14: =SUM(B5:B13) -> 36175
A15: remove Ent Center | B15: =-(B12) -> -2300
A16: remove Wet Bar | B16: =-(B13) -> -3675
A17: Reivsed base Total | B17: =SUM(B14:B16) -> 30200
A19: Modern Me Masterpiece | F19: VERNS Base 2-24-2026
A20: Kitchen Base | C20: Uprade Options | D20: Charge HO / .65 | F20: Kitchen Base
A21: Kitchen Perimeter | B21: 14436 | F21: Kitchen | G21: =15164+301 -> 15465
A22: Kitchen Island | B22: =3035+759 -> 3794
A23: Island Veneer with translucent upgrade | B23: =702+176 -> 878
A24: Hood Vent Blower only | B24: 850
A25: 18" upper cabs | C25: 3376 | D25: =C25/0.65 -> 5193.8462
A26: Custom 42" w appliance garge | C26: 751 | D26: =C26/0.65 -> 1155.3846
A27: Bathrooms Base | F27: Bathrooms Base
A28: Cabinets Bath 2 w. translucent upgrade | B28: =1785+446 -> 2231 | F28: Master | G28: =4690+140 -> 4830
A29: Cabinets bath 3 w. translucent upgrade | B29: =1017+254 -> 1271 | F29: Bath #2 | G29: =1402+42 -> 1444
A30: Cabinets master | B30: 4763 | F30: Bath #3 | G30: =887+28 -> 915
A31: Laundry Base | F31: Laundry Base
A32: Laundry Sink Side | B32: =1516+227 -> 1743 | F32: Laundry | G32: =4120+70 -> 4190
A33: Laundry Dog Crate | B33: =2082+312 -> 2394 | D33: =B33/0.65 -> 3683.0769
A34: Laundry Pantry Tower | C34: =1538+231 -> 1769 | D34: =C34/0.65 -> 2721.5385
A35: Total | B35: =SUM(B21:B34) -> 32360 | C35: =SUM(C24:C34) -> 5896 | D35: =SUM(D23:D34) -> 12753.846 | F35: Total | G35: =SUM(G21:G34) -> 26844
A36: Total Base Budget | B36: 30200 | F36: Total Base Budget | G36: 30200
A37: Over Budget | B37: =B36-B35 -> -2160 | F37: Under Budget | G37: =G36-G35 -> 3356
A39: Location Adds | B39: See tabs | F39: Verns Location Adds | G39: See Tabs
A40: Pantry | B40: =3986+598 -> 4584 | F40: Pantry | G40: =1398+42 -> 1440
A41: Fireplace wall | B41: 2004 | F41: Entertainment | G41: =1622+28 -> 1650
A42: Wetbar | B42: 2543 | F42: Wet Bar | G42: =2199+56 -> 2255
A43: Wetbar under counter fridge panel w. translucent up | B43: =454+114 -> 568
A44: Wet bar shelves and vertical dividers | B44: =6040+1510 -> 7550
...

Sheet Specialties
A1: ='DNU Customer Option Cover Page'!C6 -> Olsen Veranda Bay Model #2
A2: ='DNU Customer Option Cover Page'!C7 -> 183 Stillwater Drive, Flagler Beach
A4: Budget
A6: Bath 4 shower enclosure | B6: 1500
A7: Bath 3 glass on KW | B7: 1650
A8: Master | B8: 3500
A9: Shelving | B9: 3238
A10: Mirrors | B10: 1347
A12: Total | B12: =SUM(B6:B11) -> 11235
A13: J&H | B13: =7104.01+789.33 -> 7893.34
A14: Under Budget | B14: =B12-B13 -> 3341.66
A16: Master Bath: Shower Entry Doors Style: Arched Doors Swing: In & Out Handles: Rounded Clips: To match shower fixture finish Notes: Check vendor est. And cross reference with height of arched header.
A18: Per Plan
A19: Double doors and (2) panels | B19: 3500
A20: on 48" high knee wall to 8'
A22: Selected
A23: Arched double doors with (2) | B23: 2369.11
A24: full walls
A25: Difference | B25: =B19-B23 -> 1130.89
A26: NO Charge to HO
A28: Bath #2: Height: 8' A.F.F Style: Bypass Glass Doors Handles: Round Vertical (No Horiz. Bar) Hinge Bracket: to match plumbing fixtures in shower
A30: Per Plan
A31: Frameless bypass doors to 7' | B31: 1500
A34: Selected
A35: Frameless bypass doors to 7' | B35: 1420
A37: Difference | B37: =B31-B35 -> 80
A38: NO Charge to HO
A40: Bath #3: Glass Panel on Kneewall up to 8' A.F.F. Glass Swing Door up to 8' A.F.F. Hinge Bracket: to match shower fixtures Kneewall: 48" (See plans)
A42: Per Plan
A43: 48" h kneewall with glass to | B43: 1650
A44: 8' and door to 8'
A46: Selected
A47: 48" h kneewall with glass to | B47: 1557.23
A48: 8' and door to 8'
A49: Difference | B49: =B43-B47 -> 92.77
A50: NO Charge to HO

Sheet Base Plumbing
A1: Model - 183 Stillwater
A3: Plumbing Selection Form
O4: Base
A5: Pipe material: | B5: CPVC all areas
A6: Water Heater: | B6: 1 -Tankless heater RUR 199EP Rinnai | O6: 2600
A7: Hot water heater system: | B7: Gas
A8: Reciruit system: | B8: built in recirculating pump with transfer valve
A9: Water meter notes: | B9: 1" from water meter
A11: Utilities
A12: Washing machine: | B12: 1 | C12: recessed box with hammer arrestors
A13: Sewer lines: | C13: 4" 3034 sewer pipe
A14: Water lines: | C14: CPVC
A15: A/C chase: | C15: Include
A16: Fridge: | B16: 1
A17: Dishwasher: | B17: 1
A18: Hose bibs: | B18: 4
A21: Plumbing Fixtures | O21: Builder Cost
A22: Kitchen Island | O22: Brantford
B23: Qty
A24: Sink: | B24: 1 | C24: GSM-3218 Dakota-supplied by granite company-single bowl sink
A25: sink faucet: | B25: 1 | C25: Moen Brantford 7185ORB | O25: =459*1.07 -> 491.13
A26: Disposal: | B26: 1 | C26: 1/2 HP Insinkerator badger 5 | O26: =154.23*1.07 -> 165.0261
A27: Air switch: | C27: None
A28: Pot filler: | C28: None
A30: Laundry room
B31: Qty
A32: sink: | B32: 1 | C32: GSM-2318 Dakota-supplied by granite company
A33: sink faucet: | B33: 1 | C33: Moen Brantford 7185ORB | O33: =459*1.07 -> 491.13
A35: Pantry
B36: Qty
A37: sink: | B37: 1 | C37: GSM-2318 Dakota-supplied by granite company
A38: sink faucet: | B38: 1 | C38: Moen Brantford 7185ORB | O38: =459*1.07 -> 491.13
A40: Bar
B41: Qty
A42: sink: | B42: 1 | C42: GSM-2318 Dakota-supplied by granite company
A43: sink faucet: | B43: 1 | C43: Moen Brantford 7185ORB | O43: =459*1.07 -> 491.13
A45: Master bathroom
B46: Qty
A47: sink: | B47: 2 | C47: sinks undermount-supplied by granite company
A48: sink faucet: | B48: 2 | C48: Moen Brantford TV6620ORB with corresponding valve | O48: =600*1.07 -> 642
...

Sheet Trim
A1: ='DNU Customer Option Cover Page'!C6 -> Olsen Veranda Bay Model #2
A2: ='DNU Customer Option Cover Page'!C7 -> 183 Stillwater Drive, Flagler Beach
A4: Upgrading from platinum selection to: Style: Cove Crown Size: 5 1/4" Locations: Main Living Area Master Bedroom Suite Master Bedroom Tray Ceiling Master Bathroom Tray Ceiling
A6: Standard 5 1/4" Crown 680 LF | B6: 2227.54
A8: Cove 5 1/4" Crown 680 LF | B8: 2567.69
A10: Added Olsen Cost | B10: =B8-B6 -> 340.15
A11: Charge HO / .65 | B11: =B10/0.65 -> 523.30769
B14: NO CHARGE

Sheet Propane
A1: ='DNU Customer Option Cover Page'!C6 -> Olsen Veranda Bay Model #2
